Workbook
Name AmbBJTs: [3]FET_BJT_SCR!$T$19
Name AmbCeCap: [3]Capacitor!$T$35
Name AMBChip: [3]Resistor!$O$18
Name AmbDidoeRec: [3]Diode!$T$6
Name AMBdiodenor: [3]Diode!$T$13
Name AmbDiodeZD: [3]Diode!$T$40
Name AmbFET: [3]FET_BJT_SCR!$T$6
Name AmbFuse: '[3]Inductor_ Etc'!$P$29
Name AmbInductor: '[3]Inductor_ Etc'!$P$6
Name AmbLogicIC: [3]IC!$T$14
Name AMBphoto: [3]FET_BJT_SCR!$T$29
Name AMBRes: [3]Resistor!$O$7

Sheet Sheet3
H1: =SUM(H4:H27) -> 95770 | I1: =SUM(I4:I27) -> 95770 | K1: =SUM(K4:K27) -> 121192 | L1: =SUM(L4:L27) -> 0 | M1: =SUM(M4:M27) -> 0 | N1: =SUM(N4:N27) -> 0 | O1: =SUM(O4:O27) -> 0 | P1: =SUM(P4:P27) -> 0 | Q1: =SUM(Q4:Q27) -> 11198 | R1: =SUM(R4:R27) -> 5234 | ... V1: =SUM(V4:V27) -> 64792
B2: Cus | C2: CutoffCargo | D2: Inch | E2: Model | F2: BNCode | G2: 3in1Code(FG) | H2: PO Remain | I2: TTL Ship | J2: GAP | K2: ="O/stock"&DAY(TODAY())&"/"&MONTH(TODAY()) -> O/stock15/6 | L2: Plan | T2: TTL Plan | U2: TTLstock | V2: BALANCE
L3: 46181 | M3: =+L3+1 -> 46182 | N3: =+M3+1 -> 46183 | O3: =+N3+1 -> 46184 | P3: =+O3+1 -> 46185 | Q3: =+P3+1 -> 46186 | R3: =+Q3+1 -> 46187
B4: SEEG | C4: Waiting booking | D4: =IFERROR(VLOOKUP(G4,Infor!B:F,4,0),) -> 65" | E4: =IFERROR(VLOOKUP(G4,Infor!B:F,5,0),) -> L65CA9N_HVD | F4: BN44-01396A | G4: 0137650478CA | H4: 150 | I4: =SUM(H4:H4) -> 150 | J4: =U4-H4 -> 14092 | K4: =SUMIFS(Stock!$F:$F,Stock!$D:$D,Sheet3!G4) -> 6788 | L4: =SUMIFS(Plan!$E:$E,Plan!$C:$C,Sheet3!G4) -> 0 | M4: =SUMIFS(Plan!$F:$F,Plan!$C:$C,Sheet3!G4) -> 0 | N4: =SUMIFS(Plan!$G:$G,Plan!$C:$C,Sheet3!G4) -> 0 | O4: =SUMIFS(Plan!$H:$H,Plan!$C:$C,Sheet3!G4) -> 0 | P4: =SUMIFS(Plan!$I:$I,Plan!$C:$C,Sheet3!G4) -> 0 | Q4: =SUMIFS(Plan!$J:$J,Plan!$C:$C,Sheet3!G4) -> 2680 | R4: =SUMIFS(Plan!$K:$K,Plan!$C:$C,Sheet3!G4) -> 2074 | S4: =SUMIFS(Plan!$M:$M,Plan!$C:$C,Sheet3!G4) -> 2700 | T4: =SUM(L4:S4) -> 7454 | U4: =+K4+T4 -> 14242 | V4: =U4-I4 -> 14092
B5: SAMEX | C5: 46184.999 | D5: =IFERROR(VLOOKUP(G5,Infor!B:F,4,0),) -> 65" | E5: =IFERROR(VLOOKUP(G5,Infor!B:F,5,0),) -> L65S7_HVD | F5: BN44-01421A | G5: 0137650504CA | H5: 12961 | I5: =SUM(H5:H6) -> 17561 | J5: =(K5+M5)-H5 -> -8764 | K5: =SUMIFS(Stock!$F:$F,Stock!$D:$D,Sheet3!G5)-3867 -> 4197 | L5: =SUMIFS(Plan!$E:$E,Plan!$C:$C,Sheet3!G5) -> 0 | M5: =SUMIFS(Plan!$F:$F,Plan!$C:$C,Sheet3!G5) -> 0 | N5: =SUMIFS(Plan!$G:$G,Plan!$C:$C,Sheet3!G5) -> 0 | O5: =SUMIFS(Plan!$H:$H,Plan!$C:$C,Sheet3!G5) -> 0 | P5: =SUMIFS(Plan!$I:$I,Plan!$C:$C,Sheet3!G5) -> 0 | Q5: =SUMIFS(Plan!$J:$J,Plan!$C:$C,Sheet3!G5) -> 0 | R5: =SUMIFS(Plan!$K:$K,Plan!$C:$C,Sheet3!G5) -> 0 | S5: =SUMIFS(Plan!$M:$M,Plan!$C:$C,Sheet3!G5) -> 5500 | T5: =SUM(L5:S6) -> 5500 | U5: =+K5+T5 -> 9697 | V5: =+U5-I5 -> -7864
B6: SEDA | C6: 46182.875 | H6: 4600 | J6: =(N5+O5)-H6 -> -4600 | R6: =SUMIFS(Plan!$K:$K,Plan!$C:$C,Sheet3!G6) -> 0 | S6: =SUMIFS(Plan!$M:$M,Plan!$C:$C,Sheet3!G6) -> 0
B7: SAMEX | C7: 46184.999 | D7: =IFERROR(VLOOKUP(G7,Infor!B:F,4,0),) -> 75" | E7: =IFERROR(VLOOKUP(G7,Infor!B:F,5,0),) -> L75S7A_HVD | F7: BN44-01422B | G7: 0137750275CA | H7: 11488 | I7: =SUM(H7) -> 11488 | J7: =(K7+M7)-H7 -> -11460 | K7: =SUMIFS(Stock!$F:$F,Stock!$D:$D,Sheet3!G7) -> 28 | L7: =SUMIFS(Plan!$E:$E,Plan!$C:$C,Sheet3!G7) -> 0 | M7: =SUMIFS(Plan!$F:$F,Plan!$C:$C,Sheet3!G7) -> 0 | N7: =SUMIFS(Plan!$G:$G,Plan!$C:$C,Sheet3!G7) -> 0 | O7: =SUMIFS(Plan!$H:$H,Plan!$C:$C,Sheet3!G7) -> 0 | P7: =SUMIFS(Plan!$I:$I,Plan!$C:$C,Sheet3!G7) -> 0 | Q7: =SUMIFS(Plan!$J:$J,Plan!$C:$C,Sheet3!G7) -> 0 | R7: =SUMIFS(Plan!$K:$K,Plan!$C:$C,Sheet3!G7) -> 0 | S7: =SUMIFS(Plan!$M:$M,Plan!$C:$C,Sheet3!G7) -> 2100 | T7: =SUM(L7:S7) -> 2100 | U7: =K7+T7 -> 2128 | V7: =U7-I7 -> -9360 | W7: SO over SOP
B8: SEDA | C8: 46182.875 | D8: =IFERROR(VLOOKUP(G8,Infor!B:F,4,0),) -> 75" | E8: =IFERROR(VLOOKUP(G8,Infor!B:F,5,0),) -> L75S7_HVD | F8: BN44-01422A | G8: 0137750274CA | H8: 6500 | I8: =SUM(H8) -> 6500 | J8: =(K8+M8)-H8 -> -2078 | K8: =SUMIFS(Stock!$F:$F,Stock!$D:$D,Sheet3!G8) -> 4422 | L8: =SUMIFS(Plan!$E:$E,Plan!$C:$C,Sheet3!G8) -> 0 | M8: =SUMIFS(Plan!$F:$F,Plan!$C:$C,Sheet3!G8) -> 0 | N8: =SUMIFS(Plan!$G:$G,Plan!$C:$C,Sheet3!G8) -> 0 | O8: =SUMIFS(Plan!$H:$H,Plan!$C:$C,Sheet3!G8) -> 0 | P8: =SUMIFS(Plan!$I:$I,Plan!$C:$C,Sheet3!G8) -> 0 | Q8: =SUMIFS(Plan!$J:$J,Plan!$C:$C,Sheet3!G8) -> 0 | R8: =SUMIFS(Plan!$K:$K,Plan!$C:$C,Sheet3!G8) -> 0 | S8: =SUMIFS(Plan!$M:$M,Plan!$C:$C,Sheet3!G8) -> 0 | T8: =SUM(L8:S8) -> 0 | U8: =+K8+T8 -> 4422 | V8: =+U8-I8 -> -2078 | W8: SO over SOP
B9: SEDA | C9: 46182.875 | D9: =IFERROR(VLOOKUP(G9,Infor!B:F,4,0),) -> 55" | E9: =IFERROR(VLOOKUP(G9,Infor!B:F,5,0),) -> L55E70A_HVD | F9: BN44-01426A | G9: 0137556092CA | H9: 288 | I9: =SUM(H9) -> 288 | J9: =K9-H9 -> 7319 | K9: =SUMIFS(Stock!$F:$F,Stock!$D:$D,Sheet3!G9) -> 7607 | L9: =SUMIFS(Plan!$E:$E,Plan!$C:$C,Sheet3!G9) -> 0 | M9: =SUMIFS(Plan!$F:$F,Plan!$C:$C,Sheet3!G9) -> 0 | N9: =SUMIFS(Plan!$G:$G,Plan!$C:$C,Sheet3!G9) -> 0 | O9: =SUMIFS(Plan!$H:$H,Plan!$C:$C,Sheet3!G9) -> 0 | P9: =SUMIFS(Plan!$I:$I,Plan!$C:$C,Sheet3!G9) -> 0 | Q9: =SUMIFS(Plan!$J:$J,Plan!$C:$C,Sheet3!G9) -> 0 | R9: =SUMIFS(Plan!$K:$K,Plan!$C:$C,Sheet3!G9) -> 0 | S9: =SUMIFS(Plan!$M:$M,Plan!$C:$C,Sheet3!G9) -> 0 | T9: =SUM(L9:S9) -> 0 | U9: =+K9+T9 -> 7607 | V9: =+U9-I9 -> 7319
B10: SEDA | C10: 46183.708 | D10: =IFERROR(VLOOKUP(G11,Infor!B:F,4,0),) -> 65" | E10: =IFERROR(VLOOKUP(G11,Infor!B:F,5,0),) -> L65E70A_HVD | F10: BN44-01427A | G10: 0137650511CA | H10: 1464 | I10: =SUM(H10:H12) -> 1827 | J10: =U10-H10 -> 20231 | K10: =SUMIFS(Stock!$F:$F,Stock!$D:$D,Sheet3!G11)-528 -> 13895 | M10: =SUMIFS(Plan!$F:$F,Plan!$C:$C,Sheet3!G11) -> 0 | N10: =SUMIFS(Plan!$G:$G,Plan!$C:$C,Sheet3!G11) -> 0 | O10: =SUMIFS(Plan!$H:$H,Plan!$C:$C,Sheet3!G11) -> 0 | P10: =SUMIFS(Plan!$I:$I,Plan!$C:$C,Sheet3!G11) -> 0 | Q10: =SUMIFS(Plan!$J:$J,Plan!$C:$C,Sheet3!G11) -> 1462 | R10: =SUMIFS(Plan!$K:$K,Plan!$C:$C,Sheet3!G11) -> 0 | S10: =SUMIFS(Plan!$M:$M,Plan!$C:$C,Sheet3!G10) -> 3900 | T10: =SUM(L11:S12) -> 7800 | U10: =+K10+T10 -> 21695 | V10: =+U10-I10 -> 19868
B11: SEEG | C11: 46184.999 | G11: 0137650511CA | H11: 363 | J11: =J10-H11 -> 19868 | L11: =SUMIFS(Plan!$E:$E,Plan!$C:$C,Sheet3!G11) -> 0 | S11: =SUMIFS(Plan!$M:$M,Plan!$C:$C,Sheet3!G11) -> 3900
B12: SEDA | C12: 46183.708 | G12: 0137650511CA | S12: =SUMIFS(Plan!$M:$M,Plan!$C:$C,Sheet3!G12) -> 3900
B13: SEDA | C13: 46183.625 | D13: =IFERROR(VLOOKUP(G14,Infor!B:F,4,0),) -> 85" | E13: =IFERROR(VLOOKUP(G14,Infor!B:F,5,0),) -> L85E70NA_HVD | F13: BN44-01429A | G13: 0137850179CA | I13: =SUM(H13:H16) -> 789 | K13: =SUMIFS(Stock!$F:$F,Stock!$D:$D,Sheet3!G14)-374 -> 3056 | L13: =SUMIFS(Plan!$E:$E,Plan!$C:$C,Sheet3!G13) -> 0 | M13: =SUMIFS(Plan!$F:$F,Plan!$C:$C,Sheet3!G14) -> 0 | N13: =SUMIFS(Plan!$G:$G,Plan!$C:$C,Sheet3!G14) -> 0 | O13: =SUMIFS(Plan!$H:$H,Plan!$C:$C,Sheet3!G14) -> 0 | P13: =SUMIFS(Plan!$I:$I,Plan!$C:$C,Sheet3!G14) -> 0 | Q13: =SUMIFS(Plan!$J:$J,Plan!$C:$C,Sheet3!G14) -> 0 | R13: =SUMIFS(Plan!$K:$K,Plan!$C:$C,Sheet3!G14) -> 0 | S13: =SUMIFS(Plan!$M:$M,Plan!$C:$C,Sheet3!G13) -> 2000 | T13: =SUM(L13:S16) -> 2000 | U13: =+K13+T13 -> 5056 | V13: =+U13-I13 -> 4267
B14: SEDA | C14: 46182.875 | G14: 0137850179CA | H14: 85 | J14: 516
B15: SEEG | C15: Waiting booking | G15: 0137850179CA | H15: 500 | J15: =J14+N13+O13-H15 -> 16
B16: SEH | C16: 46185.499 | G16: 0137850179CA | H16: 204 | J16: =J15-H16 -> -188
B17: SAMEX | C17: 46184.999 | D17: =IFERROR(VLOOKUP(G17,Infor!B:F,4,0),) -> 65" | E17: =IFERROR(VLOOKUP(G17,Infor!B:F,5,0),) -> L65FE8N_HHS | F17: BN44-01441A | G17: 0137650521CA | H17: 2800 | I17: =SUM(H17:H18) -> 2910 | K17: =SUMIFS(Stock!$F:$F,Stock!$D:$D,Sheet3!G17) -> 1606 | L17: =SUMIFS(Plan!$E:$E,Plan!$C:$C,Sheet3!G17) -> 0 | M17: =SUMIFS(Plan!$F:$F,Plan!$C:$C,Sheet3!G17) -> 0 | N17: =SUMIFS(Plan!$G:$G,Plan!$C:$C,Sheet3!G17) -> 0 | O17: =SUMIFS(Plan!$H:$H,Plan!$C:$C,Sheet3!G17) -> 0 | P17: =SUMIFS(Plan!$I:$I,Plan!$C:$C,Sheet3!G17) -> 0 | Q17: =SUMIFS(Plan!$J:$J,Plan!$C:$C,Sheet3!G17) -> 1340 | R17: =SUMIFS(Plan!$K:$K,Plan!$C:$C,Sheet3!G17) -> 0 | S17: =SUMIFS(Plan!$M:$M,Plan!$C:$C,Sheet3!G17) -> 300 | T17: =SUM(L17:S17) -> 1640 | U17: =+K17+T17 -> 3246 | V17: =+U17-I17 -> 336
B18: SEEG | C18: Waiting booking | G18: 0137650521CA | H18: 110 | S18: =SUMIFS(Plan!$M:$M,Plan!$C:$C,Sheet3!G18) -> 300
B19: SEEG | C19: Waiting booking | D19: =IFERROR(VLOOKUP(G19,Infor!B:F,4,0),) -> 75" | E19: =IFERROR(VLOOKUP(G19,Infor!B:F,5,0),) -> L75S7N_HVD | F19: BN44-01422C | G19: 0137750276CA | H19: 6000 | I19: 6000 | J19: =K19-H19 -> -2550 | K19: =SUMIFS(Stock!$F:$F,Stock!$D:$D,Sheet3!G19) -> 3450 | L19: =SUMIFS(Plan!$E:$E,Plan!$C:$C,Sheet3!G19) -> 0 | M19: =SUMIFS(Plan!$F:$F,Plan!$C:$C,Sheet3!G19) -> 0 | N19: =SUMIFS(Plan!$G:$G,Plan!$C:$C,Sheet3!G19) -> 0 | O19: =SUMIFS(Plan!$H:$H,Plan!$C:$C,Sheet3!G19) -> 0 | P19: =SUMIFS(Plan!$I:$I,Plan!$C:$C,Sheet3!G19) -> 0 | Q19: =SUMIFS(Plan!$J:$J,Plan!$C:$C,Sheet3!G19) -> 0 | R19: =SUMIFS(Plan!$K:$K,Plan!$C:$C,Sheet3!G19) -> 0 | S19: =SUMIFS(Plan!$M:$M,Plan!$C:$C,Sheet3!G19) -> 2300 | T19: =SUM(L19:S19) -> 2300 | U19: =+K19+T19 -> 5750 | V19: =+U19-I19 -> -250
B20: SEEG | C20: Waiting booking | D20: =IFERROR(VLOOKUP(G20,Infor!B:F,4,0),) -> 65" | E20: =IFERROR(VLOOKUP(G20,Infor!B:F,5,0),) -> L65S8_HVD | F20: BN44-01433A | G20: 0137650496CA | H20: 1217 | I20: 1217 | J20: =K20-H20 -> 48323 | K20: =SUMIFS(Stock!$F:$F,Stock!$D:$D,Sheet3!G20) -> 49540 | L20: =SUMIFS(Plan!$E:$E,Plan!$C:$C,Sheet3!G20) -> 0 | M20: =SUMIFS(Plan!$F:$F,Plan!$C:$C,Sheet3!G20) -> 0 | N20: =SUMIFS(Plan!$G:$G,Plan!$C:$C,Sheet3!G20) -> 0 | O20: =SUMIFS(Plan!$H:$H,Plan!$C:$C,Sheet3!G20) -> 0 | P20: =SUMIFS(Plan!$I:$I,Plan!$C:$C,Sheet3!G20) -> 0 | Q20: =SUMIFS(Plan!$J:$J,Plan!$C:$C,Sheet3!G20) -> 0 | R20: =SUMIFS(Plan!$K:$K,Plan!$C:$C,Sheet3!G20) -> 0 | S20: =SUMIFS(Plan!$M:$M,Plan!$C:$C,Sheet3!G20) -> 0 | T20: =SUM(L20:S20) -> 0 | U20: =+K20+T20 -> 49540 | V20: =+U20-I20 -> 48323
B21: SEEG | C21: Waiting booking | D21: =IFERROR(VLOOKUP(G21,Infor!B:F,4,0),) -> 65" | E21: =IFERROR(VLOOKUP(G21,Infor!B:F,5,0),) -> L65S8N_HVD | F21: BN44-01433B | G21: 0137650517CA | H21: 800 | I21: =800 -> 800 | J21: =K21-H21 -> 1046 | K21: =SUMIFS(Stock!$F:$F,Stock!$D:$D,Sheet3!G21) -> 1846 | L21: =SUMIFS(Plan!$E:$E,Plan!$C:$C,Sheet3!G21) -> 0 | M21: =SUMIFS(Plan!$F:$F,Plan!$C:$C,Sheet3!G21) -> 0 | N21: =SUMIFS(Plan!$G:$G,Plan!$C:$C,Sheet3!G21) -> 0 | O21: =SUMIFS(Plan!$H:$H,Plan!$C:$C,Sheet3!G21) -> 0 | P21: =SUMIFS(Plan!$I:$I,Plan!$C:$C,Sheet3!G21) -> 0 | Q21: =SUMIFS(Plan!$J:$J,Plan!$C:$C,Sheet3!G21) -> 0 | R21: =SUMIFS(Plan!$K:$K,Plan!$C:$C,Sheet3!G21) -> 0 | S21: =SUMIFS(Plan!$M:$M,Plan!$C:$C,Sheet3!G21) -> 0 | T21: =SUM(L21:S21) -> 0 | U21: =+K21+T21 -> 1846 | V21: =+U21-I21 -> 1046
B22: SEH | C22: 46185.499 | D22: =IFERROR(VLOOKUP(G22,Infor!B:F,4,0),) -> 48" | E22: =IFERROR(VLOOKUP(G22,Infor!B:F,5,0),) -> L48CA9N_HVD | F22: BN44-01394A | G22: 0137480160CA | H22: =3035+2000 -> 5035 | I22: 5035 | J22: =K22-H22 -> 4399 | K22: =SUMIFS(Stock!$F:$F,Stock!$D:$D,Sheet3!G22) -> 9434 | L22: =SUMIFS(Plan!$E:$E,Plan!$C:$C,Sheet3!G22) -> 0 | M22: =SUMIFS(Plan!$F:$F,Plan!$C:$C,Sheet3!G22) -> 0 | N22: =SUMIFS(Plan!$G:$G,Plan!$C:$C,Sheet3!G22) -> 0 | O22: =SUMIFS(Plan!$H:$H,Plan!$C:$C,Sheet3!G22) -> 0 | P22: =SUMIFS(Plan!$I:$I,Plan!$C:$C,Sheet3!G22) -> 0 | Q22: =SUMIFS(Plan!$J:$J,Plan!$C:$C,Sheet3!G22) -> 156 | R22: =SUMIFS(Plan!$K:$K,Plan!$C:$C,Sheet3!G22) -> 0 | S22: =SUMIFS(Plan!$M:$M,Plan!$C:$C,Sheet3!G22) -> 0 | T22: =SUM(L22:S22) -> 156 | U22: =+K22+T22 -> 9590 | V22: =+U22-I22 -> 4555
B23: SEH | C23: 46185.499 | D23: =IFERROR(VLOOKUP(G23,Infor!B:F,4,0),) -> 55" | E23: =IFERROR(VLOOKUP(G23,Infor!B:F,5,0),) -> L55CA9N_HVD | F23: BN44-01395A | G23: 0137556089CA | H23: 2270 | I23: =2270 -> 2270 | J23: =SUM(K23:R23)-H23 -> 980 | K23: =SUMIFS(Stock!$F:$F,Stock!$D:$D,Sheet3!G23) -> 2076 | L23: =SUMIFS(Plan!$E:$E,Plan!$C:$C,Sheet3!G23) -> 0 | M23: =SUMIFS(Plan!$F:$F,Plan!$C:$C,Sheet3!G23) -> 0 | N23: =SUMIFS(Plan!$G:$G,Plan!$C:$C,Sheet3!G23) -> 0 | O23: =SUMIFS(Plan!$H:$H,Plan!$C:$C,Sheet3!G23) -> 0 | P23: =SUMIFS(Plan!$I:$I,Plan!$C:$C,Sheet3!G23) -> 0 | Q23: =SUMIFS(Plan!$J:$J,Plan!$C:$C,Sheet3!G23) -> 0 | R23: =SUMIFS(Plan!$K:$K,Plan!$C:$C,Sheet3!G23) -> 1174 | S23: =SUMIFS(Plan!$M:$M,Plan!$C:$C,Sheet3!G23) -> 0 | T23: =SUM(L23:S23) -> 1174 | U23: =+K23+T23 -> 3250 | V23: =+U23-I23 -> 980
B24: SEH | C24: 46185.499 | D24: =IFERROR(VLOOKUP(G24,Infor!B:F,4,0),) -> 55" | E24: =IFERROR(VLOOKUP(G24,Infor!B:F,5,0),) -> L55S7_HVD | F24: BN44-01420E | G24: 0137556113CA | H24: 25000 | I24: 25000 | J24: =U24-H24 -> -3060 | K24: =SUMIFS(Stock!$F:$F,Stock!$D:$D,Sheet3!G24) -> 12694 | L24: =SUMIFS(Plan!$E:$E,Plan!$C:$C,Sheet3!G24) -> 0 | M24: =SUMIFS(Plan!$F:$F,Plan!$C:$C,Sheet3!G24) -> 0 | N24: =SUMIFS(Plan!$G:$G,Plan!$C:$C,Sheet3!G24) -> 0 | O24: =SUMIFS(Plan!$H:$H,Plan!$C:$C,Sheet3!G24) -> 0 | P24: =SUMIFS(Plan!$I:$I,Plan!$C:$C,Sheet3!G24) -> 0 | Q24: =SUMIFS(Plan!$J:$J,Plan!$C:$C,Sheet3!G24) -> 5560 | R24: =SUMIFS(Plan!$K:$K,Plan!$C:$C,Sheet3!G24) -> 1986 | S24: =SUMIFS(Plan!$M:$M,Plan!$C:$C,Sheet3!G24) -> 1700 | T24: =SUM(L24:S24) -> 9246 | U24: =+K24+T24 -> 21940 | V24: =+U24-I24 -> -3060
B25: SEH | C25: 46185.499 | D25: =IFERROR(VLOOKUP(G25,Infor!B:F,4,0),) -> 55" | E25: =IFERROR(VLOOKUP(G25,Infor!B:F,5,0),) -> L55S7W_HVD | F25: BN44-01420H | G25: 0137556116CA | H25: 3183 | I25: 3183 | J25: =U25-H25 -> -3182 | K25: =SUMIFS(Stock!$F:$F,Stock!$D:$D,Sheet3!G25) -> 1 | L25: =SUMIFS(Plan!$E:$E,Plan!$C:$C,Sheet3!G25) -> 0 | M25: =SUMIFS(Plan!$F:$F,Plan!$C:$C,Sheet3!G25) -> 0 | N25: =SUMIFS(Plan!$G:$G,Plan!$C:$C,Sheet3!G25) -> 0 | O25: =SUMIFS(Plan!$H:$H,Plan!$C:$C,Sheet3!G25) -> 0 | P25: =SUMIFS(Plan!$I:$I,Plan!$C:$C,Sheet3!G25) -> 0 | Q25: =SUMIFS(Plan!$J:$J,Plan!$C:$C,Sheet3!G25) -> 0 | R25: =SUMIFS(Plan!$K:$K,Plan!$C:$C,Sheet3!G25) -> 0 | S25: =SUMIFS(Plan!$M:$M,Plan!$C:$C,Sheet3!G25) -> 0 | T25: =SUM(L25:S25) -> 0 | U25: =+K25+T25 -> 1 | V25: =+U25-I25 -> -3182
B26: SEH | C26: 46185.499 | D26: 55" | E26: M70H | F26: BN96-64398D | G26: 0187550437CA | H26: 10752 | I26: 10752 | J26: =U26-H26 -> -10200 | K26: =SUMIFS(Stock!$F:$F,Stock!$D:$D,Sheet3!G26) -> 552 | M26: =SUMIFS(Plan!$F:$F,Plan!$C:$C,Sheet3!G26) -> 0 | N26: =SUMIFS(Plan!$G:$G,Plan!$C:$C,Sheet3!G26) -> 0 | O26: =SUMIFS(Plan!$H:$H,Plan!$C:$C,Sheet3!G26) -> 0 | P26: =SUMIFS(Plan!$I:$I,Plan!$C:$C,Sheet3!G26) -> 0 | Q26: =SUMIFS(Plan!$J:$J,Plan!$C:$C,Sheet3!G26) -> 0 | R26: =SUMIFS(Plan!$K:$K,Plan!$C:$C,Sheet3!G26) -> 0 | T26: =SUM(L26:S26) -> 0 | U26: =+K26+T26 -> 552 | V26: =+U26-I26 -> -10200
D27: =IFERROR(VLOOKUP(G27,Infor!B:F,4,0),) -> 0 | K27: =SUMIFS(Stock!$F:$F,Stock!$D:$D,Sheet3!G27) -> 0 | L27: =SUMIFS(Plan!$E:$E,Plan!$C:$C,Sheet3!G27) -> 0 | M27: =SUMIFS(Plan!$F:$F,Plan!$C:$C,Sheet3!G27) -> 0 | N27: =SUMIFS(Plan!$G:$G,Plan!$C:$C,Sheet3!G27) -> 0 | O27: =SUMIFS(Plan!$H:$H,Plan!$C:$C,Sheet3!G27) -> 0 | P27: =SUMIFS(Plan!$I:$I,Plan!$C:$C,Sheet3!G27) -> 0 | Q27: =SUMIFS(Plan!$J:$J,Plan!$C:$C,Sheet3!G27) -> 0 | R27: =SUMIFS(Plan!$K:$K,Plan!$C:$C,Sheet3!G27) -> 0 | S27: =SUMIFS(Plan!$M:$M,Plan!$C:$C,Sheet3!G27) -> 0 | T27: =SUM(L27:S27) -> 0 | U27: =K27+T27 -> 0 | V27: =U27-I27 -> 0
I29: 963

Sheet Sheet3 (2)
H1: =SUM(H4:H47) -> 66137 | I1: =SUM(I4:I47) -> 66137 | K1: =SUM(K4:K56) -> 119326 | L1: =SUM(L4:L28) -> 0 | M1: =SUM(M4:M28) -> 0 | N1: =SUM(N4:N47) -> 0 | O1: =SUM(O4:O47) -> 0 | P1: =SUM(P4:P47) -> 0 | Q1: =SUM(Q4:Q47) -> 21221 | R1: =SUM(R4:R47) -> 14156 | S1: =SUM(S4:S28) -> 12000 | T1: =SUM(T4:T47) -> 58177 | U1: =SUM(U4:U56) -> 177503 | V1: =SUM(V4:V47) -> 103366
B2: Cus | C2: Cut off Cargo | D2: Inch | E2: Model | F2: BNCode | G2: 3in1Code(FG) | H2: PO Remain | I2: TTL Ship | J2: GAP | K2: ="O/stock"&DAY(TODAY())&"/"&MONTH(TODAY()) -> O/stock15/6 | L2: Plan | T2: TTL Plan | U2: TTLstock | V2: BALANCE
L3: 46181 | M3: =+L3+1 -> 46182 | N3: =+M3+1 -> 46183 | O3: =+N3+1 -> 46184 | P3: =+O3+1 -> 46185 | Q3: =+P3+1 -> 46186 | R3: =+Q3+1 -> 46187
A4: Ưu tiên xuất | B4: SAMEX | C4: 46184.999 | D4: =IFERROR(VLOOKUP(G4,Infor!B:F,4,0),) -> 65" | E4: =IFERROR(VLOOKUP(G4,Infor!B:F,5,0),) -> L65S7_HVD | F4: BN44-01421A | G4: 0137650504CA | I4: =SUM(H4:H4) -> 0 | J4: =U4-H4 -> 13564 | K4: =SUMIFS(Stock!$F:$F,Stock!$D:$D,'Sheet3 (2)'!G4) -> 8064 | L4: =SUMIFS(Plan!$E:$E,Plan!$C:$C,'Sheet3 (2)'!G4) -> 0 | M4: =SUMIFS(Plan!$F:$F,Plan!$C:$C,'Sheet3 (2)'!G4) -> 0 | N4: =SUMIFS(Plan!$G:$G,Plan!$C:$C,'Sheet3 (2)'!G4) -> 0 | O4: =SUMIFS(Plan!$H:$H,Plan!$C:$C,'Sheet3 (2)'!G4) -> 0 | P4: =SUMIFS(Plan!$I:$I,Plan!$C:$C,'Sheet3 (2)'!G4) -> 0 | Q4: =SUMIFS(Plan!$J:$J,Plan!$C:$C,'Sheet3 (2)'!G4) -> 0 | R4: =SUMIFS(Plan!$K:$K,Plan!$C:$C,'Sheet3 (2)'!G4) -> 0 | S4: =SUMIFS(Plan!$M:$M,Plan!$C:$C,'Sheet3 (2)'!G4) -> 5500 | T4: =SUM(L4:S4) -> 5500 | U4: =+K4+T4 -> 13564 | V4: =U4-I4 -> 13564
A5: Ưu tiên xuất | B5: SAMEX | C5: 46184.999 | D5: =IFERROR(VLOOKUP(G5,Infor!B:F,4,0),) -> 75" | E5: =IFERROR(VLOOKUP(G5,Infor!B:F,5,0),) -> L75S7A_HVD | F5: BN44-01422B | G5: 0137750275CA | I5: =SUM(H5:H6) -> 2496 | J5: 0 | K5: =SUMIFS(Stock!$F:$F,Stock!$D:$D,'Sheet3 (2)'!G5) -> 28 | L5: =SUMIFS(Plan!$E:$E,Plan!$C:$C,'Sheet3 (2)'!G5) -> 0 | M5: =SUMIFS(Plan!$F:$F,Plan!$C:$C,'Sheet3 (2)'!G5) -> 0 | N5: =SUMIFS(Plan!$G:$G,Plan!$C:$C,'Sheet3 (2)'!G5) -> 0 | O5: =SUMIFS(Plan!$H:$H,Plan!$C:$C,'Sheet3 (2)'!G5) -> 0 | P5: =SUMIFS(Plan!$I:$I,Plan!$C:$C,'Sheet3 (2)'!G5) -> 0 | Q5: =SUMIFS(Plan!$J:$J,Plan!$C:$C,'Sheet3 (2)'!G5) -> 0 | R5: =SUMIFS(Plan!$K:$K,Plan!$C:$C,'Sheet3 (2)'!G5) -> 0 | S5: =SUMIFS(Plan!$M:$M,Plan!$C:$C,'Sheet3 (2)'!G5) -> 2100 | T5: =SUM(L5:R6) -> 0 | U5: =+K5+T5 -> 28 | V5: =U5-I5 -> -2468
B6: SAMEX | C6: Waiting booking | D6: =IFERROR(VLOOKUP(G6,Infor!B:F,4,0),) -> 75" | G6: 0137750275CA | H6: 2496 | J6: 0 | L6: =SUMIFS(Plan!$E:$E,Plan!$C:$C,'Sheet3 (2)'!G6) -> 0 | M6: =SUMIFS(Plan!$F:$F,Plan!$C:$C,'Sheet3 (2)'!G6) -> 0 | S6: =SUMIFS(Plan!$M:$M,Plan!$C:$C,'Sheet3 (2)'!G6) -> 2100 | V6: =U6-I6 -> 0 | W6: Over SOP
B7: SEHC | C7: 46184.583 | D7: =IFERROR(VLOOKUP(G7,Infor!B:F,4,0),) -> 65" | E7: =IFERROR(VLOOKUP(G7,Infor!B:F,5,0),) -> L65FE8N_HHS | F7: BN44-01441A | G7: 0137650521CA | I7: =SUM(H7:H10) -> 146 | K7: =SUMIFS(Stock!$F:$F,Stock!$D:$D,'Sheet3 (2)'!G7) -> 1606 | M7: =SUMIFS(Plan!$F:$F,Plan!$C:$C,'Sheet3 (2)'!G7) -> 0 | N7: =SUMIFS(Plan!$G:$G,Plan!$C:$C,'Sheet3 (2)'!G7) -> 0 | O7: =SUMIFS(Plan!$H:$H,Plan!$C:$C,'Sheet3 (2)'!G8) -> 0 | P7: =SUMIFS(Plan!$I:$I,Plan!$C:$C,'Sheet3 (2)'!G7) -> 0 | Q7: =SUMIFS(Plan!$J:$J,Plan!$C:$C,'Sheet3 (2)'!G7) -> 1340 | R7: =SUMIFS(Plan!$K:$K,Plan!$C:$C,'Sheet3 (2)'!G7) -> 0 | T7: =SUM(N7:S10) -> 1940 | U7: =+K7+T7 -> 3546 | V7: =U7-I7 -> 3400
B8: SAMEX | C8: 46184.999 | D8: =IFERROR(VLOOKUP(G8,Infor!B:F,4,0),) -> 65" | G8: 0137650521CA | S8: =SUMIFS(Plan!$M:$M,Plan!$C:$C,'Sheet3 (2)'!G8) -> 300 | V8: =U8-I8 -> 0
B9: SEEG | C9: Waiting booking | D9: =IFERROR(VLOOKUP(G9,Infor!B:F,4,0),) -> 65" | G9: 0137650521CA | H9: 110 | J9: =(K7+O7+P7)-H9 -> 1496 | L9: =SUMIFS(Plan!$E:$E,Plan!$C:$C,'Sheet3 (2)'!G9) -> 0 | M9: =SUMIFS(Plan!$F:$F,Plan!$C:$C,'Sheet3 (2)'!G25) -> 0 | S9: =SUMIFS(Plan!$M:$M,Plan!$C:$C,'Sheet3 (2)'!G9) -> 300 | V9: =U9-I9 -> 0
B10: SIEL | C10: Waiting booking | D10: =IFERROR(VLOOKUP(G10,Infor!B:F,4,0),) -> 65" | G10: 0137650521CA | H10: 36 | J10: =J9-H10 -> 1460 | M10: =SUMIFS(Plan!$F:$F,Plan!$C:$C,'Sheet3 (2)'!G10) -> 0 | V10: =U10-I10 -> 0
B11: SEHC | C11: 46184.583 | D11: =IFERROR(VLOOKUP(G11,Infor!B:F,4,0),) -> 65" | E11: =IFERROR(VLOOKUP(G11,Infor!B:F,5,0),) -> L65E70A_HVD | F11: BN44-01427A | G11: 0137650511CA | I11: =SUM(H11:H12) -> 363 | K11: =SUMIFS(Stock!$F:$F,Stock!$D:$D,'Sheet3 (2)'!G11) -> 14423 | M11: =SUMIFS(Plan!$F:$F,Plan!$C:$C,'Sheet3 (2)'!G11) -> 0 | N11: =SUMIFS(Plan!$G:$G,Plan!$C:$C,'Sheet3 (2)'!G11) -> 0 | O11: =SUMIFS(Plan!$H:$H,Plan!$C:$C,'Sheet3 (2)'!G11) -> 0 | P11: =SUMIFS(Plan!$I:$I,Plan!$C:$C,'Sheet3 (2)'!G11) -> 0 | Q11: =SUMIFS(Plan!$J:$J,Plan!$C:$C,'Sheet3 (2)'!G11) -> 1462 | R11: =SUMIFS(Plan!$K:$K,Plan!$C:$C,'Sheet3 (2)'!G11) -> 0 | T11: =SUM(N11:S12) -> 1462 | U11: =+K11+T11 -> 15885 | V11: =U11-I11 -> 15522
B12: SEEG | C12: Waiting booking | D12: =IFERROR(VLOOKUP(G12,Infor!B:F,4,0),) -> 65" | G12: 0137650511CA | H12: 363 | J12: =(K11+O11)-H12 -> 14060 | L12: =SUMIFS(Plan!$E:$E,Plan!$C:$C,'Sheet3 (2)'!G12) -> 0 | M12: =SUMIFS(Plan!$F:$F,Plan!$C:$C,'Sheet3 (2)'!G12) -> 0 | V12: =U12-I12 -> 0
B13: SEHC | C13: 46184.583 | D13: =IFERROR(VLOOKUP(G13,Infor!B:F,4,0),) -> 65" | E13: =IFERROR(VLOOKUP(G13,Infor!B:F,5,0),) -> L65S8_HVD | F13: BN44-01433A | G13: 0137650496CA | I13: =SUM(H13:H14) -> 1217 | K13: =SUMIFS(Stock!$F:$F,Stock!$D:$D,'Sheet3 (2)'!G13) -> 49540 | L13: =SUMIFS(Plan!$E:$E,Plan!$C:$C,'Sheet3 (2)'!G13) -> 0 | M13: =SUMIFS(Plan!$F:$F,Plan!$C:$C,'Sheet3 (2)'!G13) -> 0 | N13: =SUMIFS(Plan!$G:$G,Plan!$C:$C,'Sheet3 (2)'!G13) -> 0 | O13: =SUMIFS(Plan!$H:$H,Plan!$C:$C,'Sheet3 (2)'!G13) -> 0 | P13: =SUMIFS(Plan!$I:$I,Plan!$C:$C,'Sheet3 (2)'!G13) -> 0 | Q13: =SUMIFS(Plan!$J:$J,Plan!$C:$C,'Sheet3 (2)'!G13) -> 0 | R13: =SUMIFS(Plan!$K:$K,Plan!$C:$C,'Sheet3 (2)'!G13) -> 0 | S13: =SUMIFS(Plan!$M:$M,Plan!$C:$C,'Sheet3 (2)'!G13) -> 0 | T13: =SUM(L13:S13) -> 0 | U13: =+K13+T13 -> 49540 | V13: =U13-I13 -> 48323
B14: SEEG | C14: Waiting booking | D14: =IFERROR(VLOOKUP(G14,Infor!B:F,4,0),) -> 65" | G14: 0137650496CA | H14: 1217 | J14: =K13-H14 -> 48323 | L14: =SUMIFS(Plan!$E:$E,Plan!$C:$C,'Sheet3 (2)'!G14) -> 0 | S14: =SUMIFS(Plan!$M:$M,Plan!$C:$C,'Sheet3 (2)'!G14) -> 0
B15: SEHC | C15: 46184.583 | D15: =IFERROR(VLOOKUP(G15,Infor!B:F,4,0),) -> 55" | E15: =IFERROR(VLOOKUP(G15,Infor!B:F,5,0),) -> L55E70A_HVD | F15: BN44-01426A | G15: 0137556092CA | I15: =SUM(H15:H17) -> 5336 | K15: =SUMIFS(Stock!$F:$F,Stock!$D:$D,'Sheet3 (2)'!G15) -> 7607 | L15: =SUMIFS(Plan!$E:$E,Plan!$C:$C,'Sheet3 (2)'!G15) -> 0 | M15: =SUMIFS(Plan!$F:$F,Plan!$C:$C,'Sheet3 (2)'!G15) -> 0 | N15: =SUMIFS(Plan!$G:$G,Plan!$C:$C,'Sheet3 (2)'!G15) -> 0 | O15: =SUMIFS(Plan!$H:$H,Plan!$C:$C,'Sheet3 (2)'!G15) -> 0 | P15: =SUMIFS(Plan!$I:$I,Plan!$C:$C,'Sheet3 (2)'!G15) -> 0 | Q15: =SUMIFS(Plan!$J:$J,Plan!$C:$C,'Sheet3 (2)'!G15) -> 0 | R15: =SUMIFS(Plan!$K:$K,Plan!$C:$C,'Sheet3 (2)'!G15) -> 0 | S15: =SUMIFS(Plan!$M:$M,Plan!$C:$C,'Sheet3 (2)'!G15) -> 0 | T15: =SUM(L15:S15) -> 0 | U15: =+K15+T15 -> 7607 | V15: =U15-I15 -> 2271
B16: SAMEX | C16: Waiting booking | D16: =IFERROR(VLOOKUP(G16,Infor!B:F,4,0),) -> 55" | G16: 0137556092CA | H16: 5000 | J16: =K15-H16 -> 2607 | L16: =SUMIFS(Plan!$E:$E,Plan!$C:$C,'Sheet3 (2)'!G16) -> 0 | M16: =SUMIFS(Plan!$F:$F,Plan!$C:$C,'Sheet3 (2)'!G16) -> 0 | S16: =SUMIFS(Plan!$M:$M,Plan!$C:$C,'Sheet3 (2)'!G16) -> 0 | V16: =U16-I16 -> 0
B17: SEH | C17: Waiting booking | D17: =IFERROR(VLOOKUP(G17,Infor!B:F,4,0),) -> 55" | G17: 0137556092CA | H17: 336 | J17: =J16-H17 -> 2271 | V17: =U17-I17 -> 0
B18: SEHC | C18: 46184.583 | D18: =IFERROR(VLOOKUP(G18,Infor!B:F,4,0),) -> 55" | E18: =IFERROR(VLOOKUP(G18,Infor!B:F,5,0),) -> L55E70NA_HVD | F18: BN44-01426B | G18: 0137556107CA | I18: =SUM(H18:H19) -> 1500 | K18: =SUMIFS(Stock!$F:$F,Stock!$D:$D,'Sheet3 (2)'!G18) -> 1539 | L18: =SUMIFS(Plan!$E:$E,Plan!$C:$C,'Sheet3 (2)'!G18) -> 0 | M18: =SUMIFS(Plan!$F:$F,Plan!$C:$C,'Sheet3 (2)'!G18) -> 0 | N18: =SUMIFS(Plan!$G:$G,Plan!$C:$C,'Sheet3 (2)'!G18) -> 0 | O18: =SUMIFS(Plan!$H:$H,Plan!$C:$C,'Sheet3 (2)'!G18) -> 0 | P18: =SUMIFS(Plan!$I:$I,Plan!$C:$C,'Sheet3 (2)'!G18) -> 0 | Q18: =SUMIFS(Plan!$J:$J,Plan!$C:$C,'Sheet3 (2)'!G18) -> 0 | R18: =SUMIFS(Plan!$K:$K,Plan!$C:$C,'Sheet3 (2)'!G18) -> 0 | S18: =SUMIFS(Plan!$M:$M,Plan!$C:$C,'Sheet3 (2)'!G18) -> 0 | T18: =SUM(L18:R19) -> 0 | U18: =+K18+T18 -> 1539 | V18: =U18-I18 -> 39
B19: SIEL | C19: Waiting booking | D19: =IFERROR(VLOOKUP(G19,Infor!B:F,4,0),) -> 55" | G19: 0137556107CA | H19: 1500 | J19: =(K18+O18+P18+Q18++R18)-H19 -> 39 | L19: =SUMIFS(Plan!$E:$E,Plan!$C:$C,'Sheet3 (2)'!G19) -> 0 | M19: =SUMIFS(Plan!$F:$F,Plan!$C:$C,'Sheet3 (2)'!G19) -> 0 | S19: =SUMIFS(Plan!$M:$M,Plan!$C:$C,'Sheet3 (2)'!G19) -> 0 | V19: =U19-I19 -> 0
B20: SEHC | C20: 46184.583 | D20: =IFERROR(VLOOKUP(G20,Infor!B:F,4,0),) -> 55" | E20: =IFERROR(VLOOKUP(G20,Infor!B:F,5,0),) -> L55S7_HVD | F20: BN44-01420E | G20: 0137556113CA | I20: =SUM(H20) -> 0 | J20: =(K20+N20)-H20 -> -7306 | K20: =SUMIFS(Stock!$F:$F,Stock!$D:$D,'Sheet3 (2)'!G20)-20000 -> -7306 | L20: =SUMIFS(Plan!$E:$E,Plan!$C:$C,'Sheet3 (2)'!G20) -> 0 | M20: =SUMIFS(Plan!$F:$F,Plan!$C:$C,'Sheet3 (2)'!G20) -> 0 | N20: =SUMIFS(Plan!$G:$G,Plan!$C:$C,'Sheet3 (2)'!G20) -> 0 | O20: =SUMIFS(Plan!$H:$H,Plan!$C:$C,'Sheet3 (2)'!G20) -> 0 | P20: =SUMIFS(Plan!$I:$I,Plan!$C:$C,'Sheet3 (2)'!G20) -> 0 | Q20: =SUMIFS(Plan!$J:$J,Plan!$C:$C,'Sheet3 (2)'!G20) -> 5560 | R20: =SUMIFS(Plan!$K:$K,Plan!$C:$C,'Sheet3 (2)'!G20) -> 1986 | S20: =SUMIFS(Plan!$M:$M,Plan!$C:$C,'Sheet3 (2)'!G20) -> 1700 | T20: =SUM(L20:S20) -> 9246 | U20: =+K20+T20 -> 1940 | V20: =+U20-I20 -> 1940
B21: SEHC | C21: 46184.583 | D21: =IFERROR(VLOOKUP(G21,Infor!B:F,4,0),) -> 55" | E21: =IFERROR(VLOOKUP(G21,Infor!B:F,5,0),) -> L55S7N_HVD | F21: BN44-01420G | G21: 0137556115CA | H21: 2000 | I21: =SUM(H21) -> 2000 | J21: =K21-H21 -> 2164 | K21: =SUMIFS(Stock!$F:$F,Stock!$D:$D,'Sheet3 (2)'!G21)-2000 -> 4164 | M21: =SUMIFS(Plan!$F:$F,Plan!$C:$C,'Sheet3 (2)'!G21) -> 0 | N21: =SUMIFS(Plan!$G:$G,Plan!$C:$C,'Sheet3 (2)'!G21) -> 0 | O21: =SUMIFS(Plan!$H:$H,Plan!$C:$C,'Sheet3 (2)'!G21) -> 0 | P21: =SUMIFS(Plan!$I:$I,Plan!$C:$C,'Sheet3 (2)'!G21) -> 0 | Q21: =SUMIFS(Plan!$J:$J,Plan!$C:$C,'Sheet3 (2)'!G21) -> 0 | R21: =SUMIFS(Plan!$K:$K,Plan!$C:$C,'Sheet3 (2)'!G21) -> 0 | T21: =SUM(L21:S21) -> 0 | U21: =+K21+T21 -> 4164 | V21: =U21-I21 -> 2164
B22: SEHC | C22: 46185.583 | D22: =IFERROR(VLOOKUP(G22,Infor!B:F,4,0),) -> 55" | E22: =IFERROR(VLOOKUP(G22,Infor!B:F,5,0),) -> L55F70NA_HHS | F22: BN44-01438A | G22: 0137556101CA | H22: 125 | I22: =SUM(H22) -> 125 | J22: =(K22+N22+O22+P22)-H22 -> 512 | K22: =SUMIFS(Stock!$F:$F,Stock!$D:$D,'Sheet3 (2)'!G22) -> 637 | L22: =SUMIFS(Plan!$E:$E,Plan!$C:$C,'Sheet3 (2)'!G22) -> 0 | M22: =SUMIFS(Plan!$F:$F,Plan!$C:$C,'Sheet3 (2)'!G22) -> 0 | N22: =SUMIFS(Plan!$G:$G,Plan!$C:$C,'Sheet3 (2)'!G22) -> 0 | O22: =SUMIFS(Plan!$H:$H,Plan!$C:$C,'Sheet3 (2)'!G22) -> 0 | P22: =SUMIFS(Plan!$I:$I,Plan!$C:$C,'Sheet3 (2)'!G22) -> 0 | Q22: =SUMIFS(Plan!$J:$J,Plan!$C:$C,'Sheet3 (2)'!G22) -> 2663 | R22: =SUMIFS(Plan!$K:$K,Plan!$C:$C,'Sheet3 (2)'!G22) -> 2300 | S22: =SUMIFS(Plan!$M:$M,Plan!$C:$C,'Sheet3 (2)'!G22) -> 0 | T22: =SUM(L22:S22) -> 4963 | U22: =+K22+T22 -> 5600 | V22: =U22-I22 -> 5475
D23: =IFERROR(VLOOKUP(G23,Infor!B:F,4,0),) -> 0 | E23: =IFERROR(VLOOKUP(G23,Infor!B:F,5,0),) -> 0 | F23: BN44-01420H | I23: =SUM(H23) -> 0 | J23: =U23-H23 -> 0 | K23: =SUMIFS(Stock!$F:$F,Stock!$D:$D,'Sheet3 (2)'!G23) -> 0 | N23: =SUMIFS(Plan!$G:$G,Plan!$C:$C,'Sheet3 (2)'!G23) -> 0 | O23: =SUMIFS(Plan!$H:$H,Plan!$C:$C,'Sheet3 (2)'!G23) -> 0 | P23: =SUMIFS(Plan!$I:$I,Plan!$C:$C,'Sheet3 (2)'!G23) -> 0 | Q23: =SUMIFS(Plan!$J:$J,Plan!$C:$C,'Sheet3 (2)'!G23) -> 0 | R23: =SUMIFS(Plan!$K:$K,Plan!$C:$C,'Sheet3 (2)'!G23) -> 0 | T23: =SUM(L23:S23) -> 0 | U23: =+K23+T23 -> 0 | V23: =U23-I23 -> 0
B24: SEH | C24: 46186.499 | D24: =IFERROR(VLOOKUP(G24,Infor!B:F,4,0),) -> 55" | E24: =IFERROR(VLOOKUP(G24,Infor!B:F,5,0),) -> M70H | F24: BN96-64398D | G24: 0187550437CA | H24: 10752 | I24: =SUM(H24) -> 10752 | J24: =(K24+P24)-H24 -> -10200 | K24: =SUMIFS(Stock!$F:$F,Stock!$D:$D,'Sheet3 (2)'!G24) -> 552 | N24: =SUMIFS(Plan!$G:$G,Plan!$C:$C,'Sheet3 (2)'!G24) -> 0 | O24: =SUMIFS(Plan!$H:$H,Plan!$C:$C,'Sheet3 (2)'!G24) -> 0 | P24: =SUMIFS(Plan!$I:$I,Plan!$C:$C,'Sheet3 (2)'!G24) -> 0 | Q24: =SUMIFS(Plan!$J:$J,Plan!$C:$C,'Sheet3 (2)'!G24) -> 0 | R24: =SUMIFS(Plan!$K:$K,Plan!$C:$C,'Sheet3 (2)'!G24) -> 0 | S24: =SUMIFS(Plan!$M:$M,Plan!$C:$C,'Sheet3 (2)'!G24) -> 0 | T24: =SUM(L24:S24) -> 0 | U24: =+K24+T24 -> 552 | V24: =U24-I24 -> -10200
B25: SEH | C25: 46186.499 | D25: =IFERROR(VLOOKUP(G25,Infor!B:F,4,0),) -> 48" | E25: =IFERROR(VLOOKUP(G25,Infor!B:F,5,0),) -> L48CA9N_HVD | F25: BN44-01394A | G25: 0137480160CA | I25: =SUM(H25:H26) -> 2000 | J25: =K25-H25 -> 9434 | K25: =SUMIFS(Stock!$F:$F,Stock!$D:$D,'Sheet3 (2)'!G25) -> 9434 | N25: =SUMIFS(Plan!$G:$G,Plan!$C:$C,'Sheet3 (2)'!G25) -> 0 | O25: =SUMIFS(Plan!$H:$H,Plan!$C:$C,'Sheet3 (2)'!G25) -> 0 | P25: =SUMIFS(Plan!$I:$I,Plan!$C:$C,'Sheet3 (2)'!G25) -> 0 | Q25: =SUMIFS(Plan!$J:$J,Plan!$C:$C,'Sheet3 (2)'!G25) -> 156 | R25: =SUMIFS(Plan!$K:$K,Plan!$C:$C,'Sheet3 (2)'!G25) -> 0 | T25: =SUM(L25:R26) -> 156 | U25: =K25+T25 -> 9590 | V25: =U25-I25 -> 7590
B26: SEH | C26: Waiting booking | D26: =IFERROR(VLOOKUP(G26,Infor!B:F,4,0),) -> 48" | G26: 0137480160CA | H26: 2000 | J26: =J25-H26 -> 7434 | L26: =SUMIFS(Plan!$E:$E,Plan!$C:$C,'Sheet3 (2)'!G26) -> 0 | M26: =SUMIFS(Plan!$F:$F,Plan!$C:$C,'Sheet3 (2)'!G26) -> 0 | S26: =SUMIFS(Plan!$M:$M,Plan!$C:$C,'Sheet3 (2)'!G26) -> 0 | V26: =U26-I26 -> 0
B27: SEH | C27: 46186.499 | D27: =IFERROR(VLOOKUP(G27,Infor!B:F,4,0),) -> 55" | E27: =IFERROR(VLOOKUP(G27,Infor!B:F,5,0),) -> L55CA9N_HVD | F27: BN44-01395A | G27: 0137556089CA | I27: =SUM(H27:H28) -> 4870 | J27: =(K27+O27+P27)-H27 -> 2076 | K27: =SUMIFS(Stock!$F:$F,Stock!$D:$D,'Sheet3 (2)'!G27) -> 2076 | N27: =SUMIFS(Plan!$G:$G,Plan!$C:$C,'Sheet3 (2)'!G28) -> 0 | O27: =SUMIFS(Plan!$H:$H,Plan!$C:$C,'Sheet3 (2)'!G28) -> 0 | P27: =SUMIFS(Plan!$I:$I,Plan!$C:$C,'Sheet3 (2)'!G28) -> 0 | Q27: =SUMIFS(Plan!$J:$J,Plan!$C:$C,'Sheet3 (2)'!G28) -> 0 | R27: =SUMIFS(Plan!$K:$K,Plan!$C:$C,'Sheet3 (2)'!G28) -> 1174 | T27: =SUM(N27:S28) -> 1174 | U27: =K27+T27 -> 3250 | V27: =U27-I27 -> -1620
B28: SAMEX | C28: Waiting booking | D28: =IFERROR(VLOOKUP(G28,Infor!B:F,4,0),) -> 55" | G28: 0137556089CA | H28: 4870 | J28: =(J27+R27)-H28 -> -1620 | L28: =SUMIFS(Plan!$E:$E,Plan!$C:$C,'Sheet3 (2)'!G28) -> 0 | M28: =SUMIFS(Plan!$F:$F,Plan!$C:$C,'Sheet3 (2)'!G28) -> 0 | S28: =SUMIFS(Plan!$M:$M,Plan!$C:$C,'Sheet3 (2)'!G28) -> 0 | V28: =U28-I28 -> 0
B29: SAMEX | C29: Waiting booking | D29: =IFERROR(VLOOKUP(G29,Infor!B:F,4,0),) -> 65" | E29: =IFERROR(VLOOKUP(G29,Infor!B:F,5,0),) -> L65S7A_HVD | F29: BN44-01421B | G29: 0137650505CA | H29: 20469 | I29: =SUM(H29) -> 20469 | J29: =(K29+O29+P29+Q29+R29)-H29 -> 4961 | K29: =SUMIFS(Stock!$F:$F,Stock!$D:$D,'Sheet3 (2)'!G29) -> 11448 | L29: =SUMIFS(Plan!$E:$E,Plan!$C:$C,'Sheet3 (2)'!G29) -> 0 | M29: =SUMIFS(Plan!$F:$F,Plan!$C:$C,'Sheet3 (2)'!G29) -> 0 | N29: =SUMIFS(Plan!$G:$G,Plan!$C:$C,'Sheet3 (2)'!G29) -> 0 | O29: =SUMIFS(Plan!$H:$H,Plan!$C:$C,'Sheet3 (2)'!G29) -> 0 | P29: =SUMIFS(Plan!$I:$I,Plan!$C:$C,'Sheet3 (2)'!G29) -> 0 | Q29: =SUMIFS(Plan!$J:$J,Plan!$C:$C,'Sheet3 (2)'!G29) -> 7360 | R29: =SUMIFS(Plan!$K:$K,Plan!$C:$C,'Sheet3 (2)'!G29) -> 6622 | S29: =SUMIFS(Plan!$M:$M,Plan!$C:$C,'Sheet3 (2)'!G29) -> 0 | T29: =SUM(L29:S29) -> 13982 | U29: =+K29+T29 -> 25430 | V29: =U29-I29 -> 4961
B30: SEEG | C30: Waiting booking | D30: =IFERROR(VLOOKUP(G30,Infor!B:F,4,0),) -> 65" | E30: =IFERROR(VLOOKUP(G30,Infor!B:F,5,0),) -> L65CA9N_HVD | F30: BN44-01396A | G30: 0137650478CA | H30: 150 | I30: =SUM(H30:H32) -> 6058 | J30: =(K30+O30+P30)-H30 -> 6638 | K30: =SUMIFS(Stock!$F:$F,Stock!$D:$D,'Sheet3 (2)'!G30) -> 6788 | L30: =SUMIFS(Plan!$E:$E,Plan!$C:$C,'Sheet3 (2)'!G30) -> 0 | M30: =SUMIFS(Plan!$F:$F,Plan!$C:$C,'Sheet3 (2)'!G30) -> 0 | N30: =SUMIFS(Plan!$G:$G,Plan!$C:$C,'Sheet3 (2)'!G30) -> 0 | O30: =SUMIFS(Plan!$H:$H,Plan!$C:$C,'Sheet3 (2)'!G30) -> 0 | P30: =SUMIFS(Plan!$I:$I,Plan!$C:$C,'Sheet3 (2)'!G30) -> 0 | Q30: =SUMIFS(Plan!$J:$J,Plan!$C:$C,'Sheet3 (2)'!G30) -> 2680 | R30: =SUMIFS(Plan!$K:$K,Plan!$C:$C,'Sheet3 (2)'!G30) -> 2074 | S30: =SUMIFS(Plan!$M:$M,Plan!$C:$C,'Sheet3 (2)'!G30) -> 2700 | T30: =SUM(L30:S30) -> 7454 | U30: =K30+T30 -> 14242 | V30: =U30-I30 -> 8184
B31: SAMEX | C31: Waiting booking | D31: =IFERROR(VLOOKUP(G31,Infor!B:F,4,0),) -> 65" | G31: 0137650478CA | H31: 5000 | J31: =(J30+Q30+R30)-H31 -> 6392 | L31: =SUMIFS(Plan!$E:$E,Plan!$C:$C,'Sheet3 (2)'!G31) -> 0 | M31: =SUMIFS(Plan!$F:$F,Plan!$C:$C,'Sheet3 (2)'!G31) -> 0 | S31: =SUMIFS(Plan!$M:$M,Plan!$C:$C,'Sheet3 (2)'!G31) -> 2700 | V31: =U31-I31 -> 0
B32: SEH | C32: Waiting booking | D32: =IFERROR(VLOOKUP(G32,Infor!B:F,4,0),) -> 65" | G32: 0137650478CA | H32: 908 | J32: =J31-H32 -> 5484 | L32: =SUMIFS(Plan!$E:$E,Plan!$C:$C,'Sheet3 (2)'!G32) -> 0 | M32: =SUMIFS(Plan!$F:$F,Plan!$C:$C,'Sheet3 (2)'!G32) -> 0 | S32: =SUMIFS(Plan!$M:$M,Plan!$C:$C,'Sheet3 (2)'!G32) -> 2700 | V32: =U32-I32 -> 0
B33: SEEG | C33: Waiting booking | D33: =IFERROR(VLOOKUP(G33,Infor!B:F,4,0),) -> 75" | E33: =IFERROR(VLOOKUP(G33,Infor!B:F,5,0),) -> L75S7N_HVD | F33: BN44-01422C | G33: 0137750276CA | H33: 6000 | I33: =SUM(H33) -> 6000 | J33: =K33-H33 -> -2550 | K33: =SUMIFS(Stock!$F:$F,Stock!$D:$D,'Sheet3 (2)'!G33) -> 3450 | L33: =SUMIFS(Plan!$E:$E,Plan!$C:$C,'Sheet3 (2)'!G33) -> 0 | M33: =SUMIFS(Plan!$F:$F,Plan!$C:$C,'Sheet3 (2)'!G33) -> 0 | N33: =SUMIFS(Plan!$G:$G,Plan!$C:$C,'Sheet3 (2)'!G33) -> 0 | O33: =SUMIFS(Plan!$H:$H,Plan!$C:$C,'Sheet3 (2)'!G33) -> 0 | P33: =SUMIFS(Plan!$I:$I,Plan!$C:$C,'Sheet3 (2)'!G33) -> 0 | Q33: =SUMIFS(Plan!$J:$J,Plan!$C:$C,'Sheet3 (2)'!G33) -> 0 | R33: =SUMIFS(Plan!$K:$K,Plan!$C:$C,'Sheet3 (2)'!G33) -> 0 | S33: =SUMIFS(Plan!$M:$M,Plan!$C:$C,'Sheet3 (2)'!G33) -> 2300 | T33: =SUM(L33:S33) -> 2300 | U33: =+K33+T33 -> 5750 | V33: =U33-I33 -> -250
B34: SEH | C34: 46186.499 | D34: =IFERROR(VLOOKUP(G34,Infor!B:F,4,0),) -> 85" | E34: =IFERROR(VLOOKUP(G34,Infor!B:F,5,0),) -> L85E70NA_HVD | F34: BN44-01429A | G34: 0137850179CA | I34: =SUM(H34:H38) -> 1708 | J34: =(K34+O34)-H34 -> 3430 | K34: =SUMIFS(Stock!$F:$F,Stock!$D:$D,'Sheet3 (2)'!G35) -> 3430 | L34: =SUMIFS(Plan!$E:$E,Plan!$C:$C,'Sheet3 (2)'!G34) -> 0 | M34: =SUMIFS(Plan!$F:$F,Plan!$C:$C,'Sheet3 (2)'!G34) -> 0 | N34: =SUMIFS(Plan!$G:$G,Plan!$C:$C,'Sheet3 (2)'!G14) -> 0 | O34: =SUMIFS(Plan!$H:$H,Plan!$C:$C,'Sheet3 (2)'!G35) -> 0 | P34: =SUMIFS(Plan!$I:$I,Plan!$C:$C,'Sheet3 (2)'!G35) -> 0 | Q34: =SUMIFS(Plan!$J:$J,Plan!$C:$C,'Sheet3 (2)'!G35) -> 0 | R34: =SUMIFS(Plan!$K:$K,Plan!$C:$C,'Sheet3 (2)'!G35) -> 0 | S34: =SUMIFS(Plan!$M:$M,Plan!$C:$C,'Sheet3 (2)'!G34) -> 2000 | T34: =SUM(L34:S34) -> 2000 | U34: =+K34+T34 -> 5430 | V34: =+U34-I34 -> 3722
B35: SEEG | C35: Waiting booking | D35: =IFERROR(VLOOKUP(G35,Infor!B:F,4,0),) -> 85" | G35: 0137850179CA | H35: 500 | J35: =J34-H35 -> 2930 | M35: =SUMIFS(Plan!$F:$F,Plan!$C:$C,'Sheet3 (2)'!G14) -> 0 | S35: =SUMIFS(Plan!$M:$M,Plan!$C:$C,'Sheet3 (2)'!G35) -> 2000 | T35: =SUM(L35:S35) -> 2000 | U35: =+K35+T35 -> 2000
B36: SAMEX | C36: Waiting booking | D36: =IFERROR(VLOOKUP(G36,Infor!B:F,4,0),) -> 85" | G36: 0137850179CA | H36: 963 | J36: =J35-H36 -> 1967 | L36: =SUMIFS(Plan!$E:$E,Plan!$C:$C,'Sheet3 (2)'!G36) -> 0 | M36: =SUMIFS(Plan!$F:$F,Plan!$C:$C,'Sheet3 (2)'!G36) -> 0 | S36: =SUMIFS(Plan!$M:$M,Plan!$C:$C,'Sheet3 (2)'!G36) -> 2000 | T36: =SUM(L36:S36) -> 2000 | U36: =+K36+T36 -> 2000
B37: SEH | C37: Waiting booking | D37: =IFERROR(VLOOKUP(G37,Infor!B:F,4,0),) -> 85" | G37: 0137850179CA | H37: 194 | J37: =J36-H37 -> 1773 | L37: =SUMIFS(Plan!$E:$E,Plan!$C:$C,'Sheet3 (2)'!G37) -> 0 | M37: =SUMIFS(Plan!$F:$F,Plan!$C:$C,'Sheet3 (2)'!G37) -> 0 | S37: =SUMIFS(Plan!$M:$M,Plan!$C:$C,'Sheet3 (2)'!G37) -> 2000 | T37: =SUM(L37:S37) -> 2000 | U37: =+K37+T37 -> 2000
B38: SIEL | C38: Waiting booking | D38: =IFERROR(VLOOKUP(G38,Infor!B:F,4,0),) -> 85" | G38: 0137850179CA | H38: 51 | J38: =J37-H38 -> 1722 | L38: =SUMIFS(Plan!$E:$E,Plan!$C:$C,'Sheet3 (2)'!G38) -> 0 | M38: =SUMIFS(Plan!$F:$F,Plan!$C:$C,'Sheet3 (2)'!G38) -> 0 | S38: =SUMIFS(Plan!$M:$M,Plan!$C:$C,'Sheet3 (2)'!G38) -> 2000 | T38: =SUM(L38:S38) -> 2000 | U38: =+K38+T38 -> 2000
B39: SEEG | C39: Waiting booking | D39: =IFERROR(VLOOKUP(G39,Infor!B:F,4,0),) -> 65" | E39: =IFERROR(VLOOKUP(G39,Infor!B:F,5,0),) -> L65S8N_HVD | F39: BN44-01433B | G39: 0137650517CA | H39: 800 | I39: =SUM(H39:H40) -> 1097 | J39: =K39-H39 -> 1046 | K39: =SUMIFS(Stock!$F:$F,Stock!$D:$D,'Sheet3 (2)'!G39) -> 1846 | N39: =SUMIFS(Plan!$G:$G,Plan!$C:$C,'Sheet3 (2)'!G39) -> 0 | O39: =SUMIFS(Plan!$H:$H,Plan!$C:$C,'Sheet3 (2)'!G39) -> 0 | P39: =SUMIFS(Plan!$I:$I,Plan!$C:$C,'Sheet3 (2)'!G39) -> 0 | Q39: =SUMIFS(Plan!$J:$J,Plan!$C:$C,'Sheet3 (2)'!G39) -> 0 | R39: =SUMIFS(Plan!$K:$K,Plan!$C:$C,'Sheet3 (2)'!G39) -> 0 | S39: =SUMIFS(Plan!$M:$M,Plan!$C:$C,'Sheet3 (2)'!G39) -> 0 | T39: =SUM(N39:S40) -> 0 | U39: =+K39+T39 -> 1846 | V39: =U39-I39 -> 749
B40: SIEL | C40: Waiting booking | D40: =IFERROR(VLOOKUP(G40,Infor!B:F,4,0),) -> 65" | G40: 0137650517CA | H40: 297 | J40: =J39-H40 -> 749 | L40: =SUMIFS(Plan!$E:$E,Plan!$C:$C,'Sheet3 (2)'!G40) -> 0 | M40: =SUMIFS(Plan!$F:$F,Plan!$C:$C,'Sheet3 (2)'!G40) -> 0 | S40: =SUMIFS(Plan!$M:$M,Plan!$C:$C,'Sheet3 (2)'!G40) -> 0 | V40: =U40-I40 -> 0
...

Sheet Shipment 
I1: =SUM(I4:I56) -> 181987 | J1: =SUM(J4:J31) -> 50919 | L1: =SUM(L4:L50) -> 164094 | M1: =SUM(M4:M28) -> 0 | N1: =SUM(N4:N28) -> 0 | O1: =SUM(O4:O41) -> 0 | P1: =SUM(P4:P41) -> 0 | Q1: =SUM(Q4:Q41) -> 0 | R1: =SUM(R4:R41) -> 14616 | S1: =SUM(S4:S41) -> 9870 | T1: =SUM(T4:T28) -> 19600 | U1: =SUM(U4:U41) -> 49006 | V1: =SUM(V4:V50) -> 238373 | W1: =SUM(W4:W41) -> 34300
B2: Cus | C2: Cut off Cargo | D2: HQ Request | E2: Inch | F2: Model | G2: BNCode | H2: 3in1Code(FG) | I2: PO Remain | J2: TTL Ship | K2: GAP | L2: ="O/stock"&DAY(TODAY())&"/"&MONTH(TODAY()) -> O/stock15/6 | M2: Plan | U2: TTL Plan | V2: TTLstock | W2: BALANCE
M3: 46181 | N3: =+M3+1 -> 46182 | O3: =+N3+1 -> 46183 | P3: =+O3+1 -> 46184 | Q3: =+P3+1 -> 46185 | R3: =+Q3+1 -> 46186 | S3: =+R3+1 -> 46187
E4: =IFERROR(VLOOKUP(H4,Infor!B:F,4,0),) -> 75" | F4: =IFERROR(VLOOKUP(H4,Infor!B:F,5,0),) -> L75S7N_HVD | G4: BN44-01422C | H4: 0137750276CA | K4: =L4-I4 -> 3450 | L4: =SUMIFS(Stock!$F:$F,Stock!$D:$D,'Shipment '!H4) -> 3450 | M4: =SUMIFS(Plan!$E:$E,Plan!$C:$C,'Shipment '!H4) -> 0 | N4: =SUMIFS(Plan!$F:$F,Plan!$C:$C,'Shipment '!H4) -> 0 | Q4: =SUMIFS(Plan!$I:$I,Plan!$C:$C,'Shipment '!H4) -> 0 | R4: =SUMIFS(Plan!$J:$J,Plan!$C:$C,'Shipment '!H4) -> 0 | S4: =SUMIFS(Plan!$K:$K,Plan!$C:$C,'Shipment '!H4) -> 0 | T4: =SUMIFS(Plan!$M:$M,Plan!$C:$C,'Shipment '!H4) -> 2300 | U4: =SUM(M4:T4) -> 2300 | V4: =+L4+U4 -> 5750 | W4: =V4-J4 -> 5750
B5: SEEG | C5: Waiting booking | E5: =IFERROR(VLOOKUP(H5,Infor!B:F,4,0),) -> 75" | F5: =IFERROR(VLOOKUP(H5,Infor!B:F,5,0),) -> L75S7N_HVD | H5: 0137750276CA | I5: 1584 | J5: 1584 | K5: =K4-I5 -> 1866 | M5: =SUMIFS(Plan!$E:$E,Plan!$C:$C,'Shipment '!H5) -> 0 | N5: =SUMIFS(Plan!$F:$F,Plan!$C:$C,'Shipment '!H5) -> 0 | O5: =SUMIFS(Plan!$G:$G,Plan!$C:$C,'Shipment '!H5) -> 0 | P5: =SUMIFS(Plan!$H:$H,Plan!$C:$C,'Shipment '!H5) -> 0 | Q5: =SUMIFS(Plan!$I:$I,Plan!$C:$C,'Shipment '!H5) -> 0
E6: =IFERROR(VLOOKUP(H6,Infor!B:F,4,0),) -> 65" | F6: =IFERROR(VLOOKUP(H6,Infor!B:F,5,0),) -> L65FE8N_HHS | H6: 0137650521CA | K6: =(L6+Q6)-I6 -> 1606 | L6: =SUMIFS(Stock!$F:$F,Stock!$D:$D,'Shipment '!H6) -> 1606 | N6: =SUMIFS(Plan!$F:$F,Plan!$C:$C,'Shipment '!H6) -> 0 | O6: =SUMIFS(Plan!$G:$G,Plan!$C:$C,'Shipment '!H6) -> 0 | P6: =SUMIFS(Plan!$H:$H,Plan!$C:$C,'Shipment '!H6) -> 0 | Q6: =SUMIFS(Plan!$I:$I,Plan!$C:$C,'Shipment '!H6) -> 0 | R6: =SUMIFS(Plan!$J:$J,Plan!$C:$C,'Shipment '!H6) -> 1340 | S6: =SUMIFS(Plan!$K:$K,Plan!$C:$C,'Shipment '!H6) -> 0 | U6: =SUM(M6:T6) -> 1340 | V6: =+L6+U6 -> 2946 | W6: =V6-J6 -> 2946
B7: SIEL | C7: 46189.417 | E7: =IFERROR(VLOOKUP(H7,Infor!B:F,4,0),) -> 65" | F7: =IFERROR(VLOOKUP(H7,Infor!B:F,5,0),) -> L65FE8N_HHS | H7: 0137650521CA | I7: 36 | K7: =(K6+R6)-I7 -> 2910 | Q7: =SUMIFS(Plan!$I:$I,Plan!$C:$C,'Shipment '!H7) -> 0 | T7: =SUMIFS(Plan!$M:$M,Plan!$C:$C,'Shipment '!H7) -> 300
B8: SEEG | C8: Waiting booking | E8: =IFERROR(VLOOKUP(H8,Infor!B:F,4,0),) -> 65" | F8: =IFERROR(VLOOKUP(H8,Infor!B:F,5,0),) -> L65FE8N_HHS | G8: BN44-01441A | H8: 0137650521CA | I8: 34 | J8: =SUM(I6:I8) -> 70 | K8: =K7-I8 -> 2876 | Q8: =SUMIFS(Plan!$I:$I,Plan!$C:$C,'Shipment '!H8) -> 0 | T8: =SUMIFS(Plan!$M:$M,Plan!$C:$C,'Shipment '!H8) -> 300
E9: =IFERROR(VLOOKUP(H9,Infor!B:F,4,0),) -> 65" | F9: =IFERROR(VLOOKUP(H9,Infor!B:F,5,0),) -> L65S8N_HVD | H9: 0137650517CA | K9: =L9-I9 -> 1846 | L9: =SUMIFS(Stock!$F:$F,Stock!$D:$D,'Shipment '!H9) -> 1846 | M9: =SUMIFS(Plan!$E:$E,Plan!$C:$C,'Shipment '!H9) -> 0 | N9: =SUMIFS(Plan!$F:$F,Plan!$C:$C,'Shipment '!H9) -> 0 | O9: =SUMIFS(Plan!$G:$G,Plan!$C:$C,'Shipment '!H9) -> 0 | P9: =SUMIFS(Plan!$H:$H,Plan!$C:$C,'Shipment '!H9) -> 0 | Q9: =SUMIFS(Plan!$I:$I,Plan!$C:$C,'Shipment '!H9) -> 0 | R9: =SUMIFS(Plan!$J:$J,Plan!$C:$C,'Shipment '!H9) -> 0 | S9: =SUMIFS(Plan!$K:$K,Plan!$C:$C,'Shipment '!H9) -> 0 | T9: =SUMIFS(Plan!$M:$M,Plan!$C:$C,'Shipment '!H9) -> 0 | U9: =SUM(M9:T9) -> 0 | V9: =+L9+U9 -> 1846 | W9: =V9-J9 -> 1846
B10: SIEL | C10: 46189.417 | E10: =IFERROR(VLOOKUP(H10,Infor!B:F,4,0),) -> 65" | F10: =IFERROR(VLOOKUP(H10,Infor!B:F,5,0),) -> L65S8N_HVD | H10: 0137650517CA | I10: 297 | K10: =K9-I10 -> 1549 | M10: =SUMIFS(Plan!$E:$E,Plan!$C:$C,'Shipment '!H10) -> 0 | N10: =SUMIFS(Plan!$F:$F,Plan!$C:$C,'Shipment '!H10) -> 0 | Q10: =SUMIFS(Plan!$I:$I,Plan!$C:$C,'Shipment '!H10) -> 0 | T10: =SUMIFS(Plan!$M:$M,Plan!$C:$C,'Shipment '!H10) -> 0
B11: SEEG | C11: Waiting booking | E11: =IFERROR(VLOOKUP(H11,Infor!B:F,4,0),) -> 65" | F11: =IFERROR(VLOOKUP(H11,Infor!B:F,5,0),) -> L65S8N_HVD | G11: BN44-01433B | H11: 0137650517CA | I11: 2989 | J11: 3286 | K11: =K10-I11 -> -1440 | M11: =SUMIFS(Plan!$E:$E,Plan!$C:$C,'Shipment '!H11) -> 0 | N11: =SUMIFS(Plan!$F:$F,Plan!$C:$C,'Shipment '!H11) -> 0 | Q11: =SUMIFS(Plan!$I:$I,Plan!$C:$C,'Shipment '!H11) -> 0 | T11: =SUMIFS(Plan!$M:$M,Plan!$C:$C,'Shipment '!H11) -> 0
E12: =IFERROR(VLOOKUP(H12,Infor!B:F,4,0),) -> 65" | F12: =IFERROR(VLOOKUP(H12,Infor!B:F,5,0),) -> L65CA9N_HVD | H12: 0137650478CA | K12: =(L12+Q12)-I12 -> 6788 | L12: =SUMIFS(Stock!$F:$F,Stock!$D:$D,'Shipment '!H12) -> 6788 | M12: =SUMIFS(Plan!$E:$E,Plan!$C:$C,'Shipment '!H12) -> 0 | N12: =SUMIFS(Plan!$F:$F,Plan!$C:$C,'Shipment '!H12) -> 0 | O12: =SUMIFS(Plan!$G:$G,Plan!$C:$C,'Shipment '!H12) -> 0 | P12: =SUMIFS(Plan!$H:$H,Plan!$C:$C,'Shipment '!H12) -> 0 | Q12: =SUMIFS(Plan!$I:$I,Plan!$C:$C,'Shipment '!H12) -> 0 | R12: =SUMIFS(Plan!$J:$J,Plan!$C:$C,'Shipment '!H12) -> 2680 | S12: =SUMIFS(Plan!$K:$K,Plan!$C:$C,'Shipment '!H12) -> 2074 | T12: =SUMIFS(Plan!$M:$M,Plan!$C:$C,'Shipment '!H12) -> 2700 | U12: =SUM(M12:T12) -> 7454 | V12: =+L12+U12 -> 14242 | W12: =V12-J12 -> 14242
B13: SAMEX | C13: 46191.999 | E13: =IFERROR(VLOOKUP(H13,Infor!B:F,4,0),) -> 65" | F13: =IFERROR(VLOOKUP(H13,Infor!B:F,5,0),) -> L65CA9N_HVD | H13: 0137650478CA | I13: 5000 | K13: =(K12+R12+S12)-I13 -> 6542 | O13: =SUMIFS(Plan!$G:$G,Plan!$C:$C,'Shipment '!H13) -> 0 | P13: =SUMIFS(Plan!$H:$H,Plan!$C:$C,'Shipment '!H13) -> 0 | Q13: =SUMIFS(Plan!$I:$I,Plan!$C:$C,'Shipment '!H13) -> 0
B14: SEH (PD) | C14: Waiting booking | D14: 46191 | E14: =IFERROR(VLOOKUP(H14,Infor!B:F,4,0),) -> 65" | F14: =IFERROR(VLOOKUP(H14,Infor!B:F,5,0),) -> L65CA9N_HVD | H14: 0137650478CA | I14: 908 | K14: =K13-I14 -> 5634 | N14: =SUMIFS(Plan!$F:$F,Plan!$C:$C,'Shipment '!H14) -> 0 | O14: =SUMIFS(Plan!$G:$G,Plan!$C:$C,'Shipment '!H14) -> 0 | P14: =SUMIFS(Plan!$H:$H,Plan!$C:$C,'Shipment '!H25) -> 0 | Q14: =SUMIFS(Plan!$I:$I,Plan!$C:$C,'Shipment '!H14) -> 0
B15: SEEG | C15: Waiting booking | E15: =IFERROR(VLOOKUP(H15,Infor!B:F,4,0),) -> 65" | F15: =IFERROR(VLOOKUP(H15,Infor!B:F,5,0),) -> L65CA9N_HVD | G15: BN44-01396A | H15: 0137650478CA | I15: 34 | J15: =SUM(I12:I15) -> 5942 | K15: =K14-I15 -> 5600 | N15: =SUMIFS(Plan!$F:$F,Plan!$C:$C,'Shipment '!H15) -> 0 | O15: =SUMIFS(Plan!$G:$G,Plan!$C:$C,'Shipment '!H15) -> 0 | P15: =SUMIFS(Plan!$H:$H,Plan!$C:$C,'Shipment '!H15) -> 0 | Q15: =SUMIFS(Plan!$I:$I,Plan!$C:$C,'Shipment '!H15) -> 0
E16: =IFERROR(VLOOKUP(H16,Infor!B:F,4,0),) -> 65" | F16: =IFERROR(VLOOKUP(H16,Infor!B:F,5,0),) -> L65E70A_HVD | G16: BN44-01427A | H16: 0137650511CA | J16: =SUM(I16) -> 0 | K16: =(L16+Q16)-I16 -> 14423 | L16: =SUMIFS(Stock!$F:$F,Stock!$D:$D,'Shipment '!H16) -> 14423 | Q16: =SUMIFS(Plan!$I:$I,Plan!$C:$C,'Shipment '!H16) -> 0 | R16: =SUMIFS(Plan!$J:$J,Plan!$C:$C,'Shipment '!H16) -> 1462 | S16: =SUMIFS(Plan!$K:$K,Plan!$C:$C,'Shipment '!H16) -> 0 | T16: =SUMIFS(Plan!$M:$M,Plan!$C:$C,'Shipment '!H16) -> 3900 | U16: =SUM(M16:T16) -> 5362 | V16: =+L16+U16 -> 19785 | W16: =V16-J16 -> 19785
B17: SIEL | C17: 46189.417 | E17: =IFERROR(VLOOKUP(H17,Infor!B:F,4,0),) -> 85" | F17: =IFERROR(VLOOKUP(H17,Infor!B:F,5,0),) -> L85E70NA_HVD | H17: 0137850179CA | I17: 51 | K17: =L17-I17 -> 3379 | L17: =SUMIFS(Stock!$F:$F,Stock!$D:$D,'Shipment '!H17) -> 3430 | M17: =SUMIFS(Plan!$E:$E,Plan!$C:$C,'Shipment '!H17) -> 0 | N17: =SUMIFS(Plan!$F:$F,Plan!$C:$C,'Shipment '!H17) -> 0 | O17: =SUMIFS(Plan!$G:$G,Plan!$C:$C,'Shipment '!H17) -> 0 | P17: =SUMIFS(Plan!$H:$H,Plan!$C:$C,'Shipment '!H17) -> 0 | Q17: =SUMIFS(Plan!$I:$I,Plan!$C:$C,'Shipment '!H17) -> 0 | R17: =SUMIFS(Plan!$J:$J,Plan!$C:$C,'Shipment '!H17) -> 0 | S17: =SUMIFS(Plan!$K:$K,Plan!$C:$C,'Shipment '!H17) -> 0 | T17: =SUMIFS(Plan!$M:$M,Plan!$C:$C,'Shipment '!H17) -> 2000 | U17: =SUM(M17:T17) -> 2000 | V17: =L17+U17 -> 5430 | W17: =V17-J17 -> 5430
B18: SAMEX | C18: 46191.999 | E18: =IFERROR(VLOOKUP(H18,Infor!B:F,4,0),) -> 85" | F18: =IFERROR(VLOOKUP(H18,Infor!B:F,5,0),) -> L85E70NA_HVD | H18: 0137850179CA | I18: 963 | K18: =K17-I18 -> 2416 | M18: =SUMIFS(Plan!$E:$E,Plan!$C:$C,'Shipment '!H18) -> 0 | N18: =SUMIFS(Plan!$F:$F,Plan!$C:$C,'Shipment '!H18) -> 0 | Q18: =SUMIFS(Plan!$I:$I,Plan!$C:$C,'Shipment '!H18) -> 0 | T18: =SUMIFS(Plan!$M:$M,Plan!$C:$C,'Shipment '!H18) -> 2000
B19: SEH (PD) | C19: Waiting booking | D19: 46191 | E19: =IFERROR(VLOOKUP(H19,Infor!B:F,4,0),) -> 85" | F19: =IFERROR(VLOOKUP(H19,Infor!B:F,5,0),) -> L85E70NA_HVD | H19: 0137850179CA | I19: 194 | K19: =K18-I19 -> 2222 | M19: =SUMIFS(Plan!$E:$E,Plan!$C:$C,'Shipment '!H19) -> 0 | N19: =SUMIFS(Plan!$F:$F,Plan!$C:$C,'Shipment '!H13) -> 0 | Q19: =SUMIFS(Plan!$I:$I,Plan!$C:$C,'Shipment '!H19) -> 0 | T19: =SUMIFS(Plan!$M:$M,Plan!$C:$C,'Shipment '!H19) -> 2000
B20: SEEG | C20: Waiting booking | E20: =IFERROR(VLOOKUP(H20,Infor!B:F,4,0),) -> 85" | F20: =IFERROR(VLOOKUP(H20,Infor!B:F,5,0),) -> L85E70NA_HVD | G20: BN44-01429A | H20: 0137850179CA | I20: 510 | J20: =SUM(I17:I20) -> 1718 | K20: =K19-I20 -> 1712 | N20: =SUMIFS(Plan!$F:$F,Plan!$C:$C,'Shipment '!#REF!) -> 0 | Q20: =SUMIFS(Plan!$I:$I,Plan!$C:$C,'Shipment '!H20) -> 0 | T20: =SUMIFS(Plan!$M:$M,Plan!$C:$C,'Shipment '!H20) -> 2000
B21: SIEL | C21: 46189.417 | E21: =IFERROR(VLOOKUP(H21,Infor!B:F,4,0),) -> 55" | F21: =IFERROR(VLOOKUP(H21,Infor!B:F,5,0),) -> L55E70NA_HVD | G21: BN44-01426B | H21: 0137556107CA | I21: 1500 | J21: =SUM(I21) -> 1500 | K21: =(L21+Q21)-I21 -> 39 | L21: =SUMIFS(Stock!$F:$F,Stock!$D:$D,'Shipment '!H21) -> 1539 | M21: =SUMIFS(Plan!$E:$E,Plan!$C:$C,'Shipment '!H21) -> 0 | N21: =SUMIFS(Plan!$F:$F,Plan!$C:$C,'Shipment '!H21) -> 0 | O21: =SUMIFS(Plan!$G:$G,Plan!$C:$C,'Shipment '!H21) -> 0 | P21: =SUMIFS(Plan!$H:$H,Plan!$C:$C,'Shipment '!H21) -> 0 | Q21: =SUMIFS(Plan!$I:$I,Plan!$C:$C,'Shipment '!H21) -> 0 | R21: =SUMIFS(Plan!$J:$J,Plan!$C:$C,'Shipment '!H21) -> 0 | S21: =SUMIFS(Plan!$K:$K,Plan!$C:$C,'Shipment '!H21) -> 0 | T21: =SUMIFS(Plan!$M:$M,Plan!$C:$C,'Shipment '!H21) -> 0 | U21: =SUM(M21:T21) -> 0 | V21: =+L21+U21 -> 1539 | W21: =V21-J21 -> 39
B22: SAMEX | C22: 46191.999 | E22: =IFERROR(VLOOKUP(H22,Infor!B:F,4,0),) -> 65" | F22: =IFERROR(VLOOKUP(H22,Infor!B:F,5,0),) -> L65S7A_HVD | G22: BN44-01421B | H22: 0137650505CA | I22: 20469 | J22: =SUM(I22) -> 20469 | K22: =(L22+Q22+R22+S22)-I22 -> 4961 | L22: =SUMIFS(Stock!$F:$F,Stock!$D:$D,'Shipment '!H22) -> 11448 | M22: =SUMIFS(Plan!$E:$E,Plan!$C:$C,'Shipment '!H22) -> 0 | N22: =SUMIFS(Plan!$F:$F,Plan!$C:$C,'Shipment '!H22) -> 0 | O22: =SUMIFS(Plan!$G:$G,Plan!$C:$C,'Shipment '!H22) -> 0 | P22: =SUMIFS(Plan!$H:$H,Plan!$C:$C,'Shipment '!H22) -> 0 | Q22: =SUMIFS(Plan!$I:$I,Plan!$C:$C,'Shipment '!H22) -> 0 | R22: =SUMIFS(Plan!$J:$J,Plan!$C:$C,'Shipment '!H22) -> 7360 | S22: =SUMIFS(Plan!$K:$K,Plan!$C:$C,'Shipment '!H22) -> 6622 | T22: =SUMIFS(Plan!$M:$M,Plan!$C:$C,'Shipment '!H22) -> 0 | U22: =SUM(M22:T22) -> 13982 | V22: =+L22+U22 -> 25430 | W22: =V22-J22 -> 4961
B23: SAMEX | C23: 46191.999 | E23: =IFERROR(VLOOKUP(H23,Infor!B:F,4,0),) -> 55" | F23: =IFERROR(VLOOKUP(H23,Infor!B:F,5,0),) -> L55E70A_HVD | H23: 0137556092CA | I23: 3600 | K23: =L23-I23 -> 4007 | L23: =SUMIFS(Stock!$F:$F,Stock!$D:$D,'Shipment '!H23) -> 7607 | O23: =SUMIFS(Plan!$G:$G,Plan!$C:$C,'Shipment '!H23) -> 0 | P23: =SUMIFS(Plan!$H:$H,Plan!$C:$C,'Shipment '!H23) -> 0 | Q23: =SUMIFS(Plan!$I:$I,Plan!$C:$C,'Shipment '!H23) -> 0 | R23: =SUMIFS(Plan!$J:$J,Plan!$C:$C,'Shipment '!H23) -> 0 | S23: =SUMIFS(Plan!$K:$K,Plan!$C:$C,'Shipment '!H23) -> 0 | U23: =SUM(M23:T23) -> 0 | V23: =+L23+U23 -> 7607 | W23: =V23-J23 -> 7607
B24: SAMEX | C24: 46191.999 | E24: =IFERROR(VLOOKUP(H24,Infor!B:F,4,0),) -> 55" | F24: =IFERROR(VLOOKUP(H24,Infor!B:F,5,0),) -> L55E70A_HVD | H24: 0137556092CA | I24: 1400 | K24: =K23-I24 -> 2607 | O24: =SUMIFS(Plan!$G:$G,Plan!$C:$C,'Shipment '!H18) -> 0 | P24: =SUMIFS(Plan!$H:$H,Plan!$C:$C,'Shipment '!H18) -> 0 | Q24: =SUMIFS(Plan!$I:$I,Plan!$C:$C,'Shipment '!H24) -> 0
B25: SEH (PD) | C25: Waiting booking | D25: 46191 | E25: =IFERROR(VLOOKUP(H25,Infor!B:F,4,0),) -> 55" | F25: =IFERROR(VLOOKUP(H25,Infor!B:F,5,0),) -> L55E70A_HVD | H25: 0137556092CA | I25: 336 | K25: =K24-I25 -> 2271 | Q25: =SUMIFS(Plan!$I:$I,Plan!$C:$C,'Shipment '!H25) -> 0 | T25: =SUMIFS(Plan!$M:$M,Plan!$C:$C,'Shipment '!H25) -> 0
B26: SEEG | C26: Waiting booking | E26: =IFERROR(VLOOKUP(H26,Infor!B:F,4,0),) -> 55" | F26: =IFERROR(VLOOKUP(H26,Infor!B:F,5,0),) -> L55E70A_HVD | G26: BN44-01426A | H26: 0137556092CA | I26: 708 | J26: =SUM(I23:I26) -> 6044 | K26: =K25-I26 -> 1563 | M26: =SUMIFS(Plan!$E:$E,Plan!$C:$C,'Shipment '!H26) -> 0 | N26: =SUMIFS(Plan!$F:$F,Plan!$C:$C,'Shipment '!H26) -> 0 | O26: =SUMIFS(Plan!$G:$G,Plan!$C:$C,'Shipment '!#REF!) -> 0 | P26: =SUMIFS(Plan!$H:$H,Plan!$C:$C,'Shipment '!H20) -> 0 | Q26: =SUMIFS(Plan!$I:$I,Plan!$C:$C,'Shipment '!H26) -> 0 | T26: =SUMIFS(Plan!$M:$M,Plan!$C:$C,'Shipment '!H26) -> 0
B27: SAMEX | C27: 46191.999 | E27: =IFERROR(VLOOKUP(H27,Infor!B:F,4,0),) -> 55" | F27: =IFERROR(VLOOKUP(H27,Infor!B:F,5,0),) -> L55CA9N_HVD | G27: BN44-01395A | H27: 0137556089CA | I27: 4870 | J27: =SUM(I27) -> 4870 | K27: =(L27+Q27+R27+S27)-I27 -> -1620 | L27: =SUMIFS(Stock!$F:$F,Stock!$D:$D,'Shipment '!H27) -> 2076 | O27: =SUMIFS(Plan!$G:$G,Plan!$C:$C,'Shipment '!H27) -> 0 | P27: =SUMIFS(Plan!$H:$H,Plan!$C:$C,'Shipment '!H27) -> 0 | Q27: =SUMIFS(Plan!$I:$I,Plan!$C:$C,'Shipment '!H27) -> 0 | R27: =SUMIFS(Plan!$J:$J,Plan!$C:$C,'Shipment '!H27) -> 0 | S27: =SUMIFS(Plan!$K:$K,Plan!$C:$C,'Shipment '!H27) -> 1174 | T27: =SUMIFS(Plan!$M:$M,Plan!$C:$C,'Shipment '!H27) -> 0 | U27: =SUM(M27:T27) -> 1174 | V27: =+L27+U27 -> 3250 | W27: =V27-J27 -> -1620
B28: SAMEX | C28: 46191.999 | E28: =IFERROR(VLOOKUP(H28,Infor!B:F,4,0),) -> 75" | F28: =IFERROR(VLOOKUP(H28,Infor!B:F,5,0),) -> L75S7A_HVD | G28: BN44-01422B | H28: 0137750275CA | I28: 2496 | J28: =I28 -> 2496 | K28: =L28-I28 -> -2468 | L28: =SUMIFS(Stock!$F:$F,Stock!$D:$D,'Shipment '!H28) -> 28 | M28: =SUMIFS(Plan!$E:$E,Plan!$C:$C,'Shipment '!H28) -> 0 | N28: =SUMIFS(Plan!$F:$F,Plan!$C:$C,'Shipment '!H28) -> 0 | Q28: =SUMIFS(Plan!$I:$I,Plan!$C:$C,'Shipment '!H28) -> 0 | R28: =SUMIFS(Plan!$J:$J,Plan!$C:$C,'Shipment '!H28) -> 0 | S28: =SUMIFS(Plan!$K:$K,Plan!$C:$C,'Shipment '!H28) -> 0 | T28: =SUMIFS(Plan!$M:$M,Plan!$C:$C,'Shipment '!H28) -> 2100 | U28: =SUM(M28:T28) -> 2100 | V28: =+L28+U28 -> 2128 | W28: =V28-J28 -> -368
B29: SEH (PD) | C29: Waiting booking | D29: 46191 | E29: =IFERROR(VLOOKUP(H29,Infor!B:F,4,0),) -> 48" | F29: =IFERROR(VLOOKUP(H29,Infor!B:F,5,0),) -> L48CA9N_HVD | H29: 0137480160CA | I29: 2000 | K29: =(L29+Q29+R29+S29)-I29 -> 7590 | L29: =SUMIFS(Stock!$F:$F,Stock!$D:$D,'Shipment '!H29) -> 9434 | M29: =SUMIFS(Plan!$E:$E,Plan!$C:$C,'Shipment '!H29) -> 0 | N29: =SUMIFS(Plan!$F:$F,Plan!$C:$C,'Shipment '!H29) -> 0 | Q29: =SUMIFS(Plan!$I:$I,Plan!$C:$C,'Shipment '!H29) -> 0 | R29: =SUMIFS(Plan!$J:$J,Plan!$C:$C,'Shipment '!H29) -> 156 | S29: =SUMIFS(Plan!$K:$K,Plan!$C:$C,'Shipment '!H29) -> 0 | T29: =SUMIFS(Plan!$M:$M,Plan!$C:$C,'Shipment '!H29) -> 0 | U29: =SUM(M29:T29) -> 156 | V29: =+L29+U29 -> 9590 | W29: =V29-J29 -> 9590
B30: SEEG | C30: Waiting booking | E30: =IFERROR(VLOOKUP(H30,Infor!B:F,4,0),) -> 48" | F30: =IFERROR(VLOOKUP(H30,Infor!B:F,5,0),) -> L48CA9N_HVD | G30: BN44-01394A | H30: 0137480160CA | I30: 40 | J30: =SUM(I29:I30) -> 2040 | K30: =K29-I30 -> 7550 | L30: =SUMIFS(Stock!$F:$F,Stock!$D:$D,'Shipment '!H30) -> 9434 | N30: =SUMIFS(Plan!$F:$F,Plan!$C:$C,'Shipment '!H30) -> 0 | Q30: =SUMIFS(Plan!$I:$I,Plan!$C:$C,'Shipment '!H30) -> 0 | R30: =SUMIFS(Plan!$J:$J,Plan!$C:$C,'Shipment '!H30) -> 156 | S30: =SUMIFS(Plan!$K:$K,Plan!$C:$C,'Shipment '!H30) -> 0 | T30: =SUMIFS(Plan!$M:$M,Plan!$C:$C,'Shipment '!H30) -> 0 | U30: =SUM(M30:T30) -> 156 | V30: =+L30+U30 -> 9590 | W30: =V30-J30 -> 7550
B31: SEEG | C31: Waiting booking | E31: =IFERROR(VLOOKUP(H31,Infor!B:F,4,0),) -> 65" | F31: =IFERROR(VLOOKUP(H31,Infor!B:F,5,0),) -> L65S7_HVD | G31: BN44-01421A | H31: 0137650504CA | I31: 900 | J31: =SUM(I31) -> 900 | K31: =(L31+Q31)-I31 -> 7164 | L31: =SUMIFS(Stock!$F:$F,Stock!$D:$D,'Shipment '!H31) -> 8064 | M31: =SUMIFS(Plan!$E:$E,Plan!$C:$C,'Shipment '!H31) -> 0 | N31: =SUMIFS(Plan!$F:$F,Plan!$C:$C,'Shipment '!H31) -> 0 | Q31: =SUMIFS(Plan!$I:$I,Plan!$C:$C,'Shipment '!H31) -> 0 | R31: =SUMIFS(Plan!$J:$J,Plan!$C:$C,'Shipment '!H31) -> 0 | S31: =SUMIFS(Plan!$K:$K,Plan!$C:$C,'Shipment '!H31) -> 0 | T31: =SUMIFS(Plan!$M:$M,Plan!$C:$C,'Shipment '!H31) -> 5500 | U31: =SUM(M31:T31) -> 5500 | V31: =+L31+U31 -> 13564 | W31: =V31-J31 -> 12664
E32: =IFERROR(VLOOKUP(H32,Infor!B:F,4,0),) -> 0 | F32: =IFERROR(VLOOKUP(H32,Infor!B:F,5,0),) -> 0 | J32: =SUM(I32:I33) -> 340 | L32: =SUMIFS(Stock!$F:$F,Stock!$D:$D,'Shipment '!H32) -> 0 | M32: =SUMIFS(Plan!$E:$E,Plan!$C:$C,'Shipment '!H32) -> 0 | N32: =SUMIFS(Plan!$F:$F,Plan!$C:$C,'Shipment '!H32) -> 0 | T32: =SUMIFS(Plan!$M:$M,Plan!$C:$C,'Shipment '!H32) -> 0 | U32: =SUM(M32:T32) -> 0 | V32: =+L32+U32 -> 0
B33: SEH (3in1) | C33: Waiting booking | D33: 46195 | E33: =IFERROR(VLOOKUP(H33,Infor!B:F,4,0),) -> 65" | F33: =IFERROR(VLOOKUP(H33,Infor!B:F,5,0),) -> U8000F | G33: BN96-62547D | H33: 0187650250CA | I33: 340 | J33: =SUM(I33:I34) -> 420 | L33: =SUMIFS(Stock!$F:$F,Stock!$D:$D,'Shipment '!H33) -> 0 | O33: =SUMIFS(Plan!$G:$G,Plan!$C:$C,'Shipment '!H33) -> 0 | P33: =SUMIFS(Plan!$H:$H,Plan!$C:$C,'Shipment '!H33) -> 0 | Q33: =SUMIFS(Plan!$I:$I,Plan!$C:$C,'Shipment '!H33) -> 0 | R33: =SUMIFS(Plan!$J:$J,Plan!$C:$C,'Shipment '!H33) -> 0 | S33: =SUMIFS(Plan!$K:$K,Plan!$C:$C,'Shipment '!H33) -> 0 | T33: =SUMIFS(Plan!$M:$M,Plan!$C:$C,'Shipment '!H33) -> 340 | U33: =SUM(M33:T33) -> 340 | V33: =+L33+U33 -> 340 | W33: =V33-J33 -> -80
B34: SEH (3in1) | C34: Waiting booking | D34: 46195 | E34: =IFERROR(VLOOKUP(H34,Infor!B:F,4,0),) -> 75" | F34: =IFERROR(VLOOKUP(H34,Infor!B:F,5,0),) -> U8000F | G34: BN96-62547C | H34: 0187750077CA | I34: 80 | J34: =SUM(I34:I35) -> 11080 | M34: =SUMIFS(Plan!$E:$E,Plan!$C:$C,'Shipment '!H34) -> 0 | N34: =SUMIFS(Plan!$F:$F,Plan!$C:$C,'Shipment '!H34) -> 0 | T34: =SUMIFS(Plan!$M:$M,Plan!$C:$C,'Shipment '!H34) -> 80 | U34: =SUM(M34:T34) -> 80 | W34: =V34-J34 -> -11080
B35: SEH (3in1) | C35: Waiting booking | D35: 46195 | E35: =IFERROR(VLOOKUP(H35,Infor!B:F,4,0),) -> 55" | F35: =IFERROR(VLOOKUP(H35,Infor!B:F,5,0),) -> U8000H | G35: BN96-64397X | H35: 0187550426CA | I35: 11000 | J35: =SUM(I35:I36) -> 22136 | L35: =SUMIFS(Stock!$F:$F,Stock!$D:$D,'Shipment '!H35) -> 0 | M35: =SUMIFS(Plan!$E:$E,Plan!$C:$C,'Shipment '!H35) -> 0 | N35: =SUMIFS(Plan!$F:$F,Plan!$C:$C,'Shipment '!H35) -> 0 | O35: =SUMIFS(Plan!$G:$G,Plan!$C:$C,'Shipment '!H35) -> 0 | P35: =SUMIFS(Plan!$H:$H,Plan!$C:$C,'Shipment '!H35) -> 0 | Q35: =SUMIFS(Plan!$I:$I,Plan!$C:$C,'Shipment '!H35) -> 0 | R35: =SUMIFS(Plan!$J:$J,Plan!$C:$C,'Shipment '!H35) -> 0 | S35: =SUMIFS(Plan!$K:$K,Plan!$C:$C,'Shipment '!H35) -> 0 | T35: =SUMIFS(Plan!$M:$M,Plan!$C:$C,'Shipment '!H35) -> 3600 | U35: =SUM(M35:T35) -> 3600 | V35: =+L35+U35 -> 3600 | W35: =V35-J35 -> -18536
B36: SEH (3in1) | C36: Waiting booking | D36: 46195 | E36: =IFERROR(VLOOKUP(H36,Infor!B:F,4,0),) -> 55" | F36: =IFERROR(VLOOKUP(H36,Infor!B:F,5,0),) -> M70H | G36: BN96-64398D | H36: 0187550437CA | I36: 11136 | J36: =SUM(I36:I36) -> 11136 | L36: =SUMIFS(Stock!$F:$F,Stock!$D:$D,'Shipment '!H36) -> 552 | M36: =SUMIFS(Plan!$E:$E,Plan!$C:$C,'Shipment '!H36) -> 0 | N36: =SUMIFS(Plan!$F:$F,Plan!$C:$C,'Shipment '!H36) -> 0 | O36: =SUMIFS(Plan!$G:$G,Plan!$C:$C,'Shipment '!H36) -> 0 | P36: =SUMIFS(Plan!$H:$H,Plan!$C:$C,'Shipment '!H36) -> 0 | Q36: =SUMIFS(Plan!$I:$I,Plan!$C:$C,'Shipment '!H36) -> 0 | R36: =SUMIFS(Plan!$J:$J,Plan!$C:$C,'Shipment '!H36) -> 0 | S36: =SUMIFS(Plan!$K:$K,Plan!$C:$C,'Shipment '!H36) -> 0 | T36: =SUMIFS(Plan!$M:$M,Plan!$C:$C,'Shipment '!H36) -> 0 | U36: =SUM(M36:T36) -> 0 | V36: =+L36+U36 -> 552 | W36: =V36-J36 -> -10584
B37: SEDA | C37: Waiting booking | E37: =IFERROR(VLOOKUP(H37,Infor!B:F,4,0),) -> 65" | F37: =IFERROR(VLOOKUP(H37,Infor!B:F,5,0),) -> L65S7_HVD | G37: BN44-01421A | H37: 0137650504CA | I37: 13500 | J37: =SUM(I32:I38) -> 41056 | L37: =SUMIFS(Stock!$F:$F,Stock!$D:$D,'Shipment '!H37) -> 8064 | N37: =SUMIFS(Plan!$F:$F,Plan!$C:$C,'Shipment '!H37) -> 0 | O37: =SUMIFS(Plan!$G:$G,Plan!$C:$C,'Shipment '!H37) -> 0 | P37: =SUMIFS(Plan!$H:$H,Plan!$C:$C,'Shipment '!H37) -> 0 | Q37: =SUMIFS(Plan!$I:$I,Plan!$C:$C,'Shipment '!H37) -> 0 | R37: =SUMIFS(Plan!$J:$J,Plan!$C:$C,'Shipment '!H37) -> 0 | S37: =SUMIFS(Plan!$K:$K,Plan!$C:$C,'Shipment '!H37) -> 0 | U37: =SUM(M37:T37) -> 0 | V37: =+L37+U37 -> 8064 | W37: =V37-J37 -> -32992
B38: SEDA | C38: Waiting booking | E38: =IFERROR(VLOOKUP(H38,Infor!B:F,4,0),) -> 75" | F38: =IFERROR(VLOOKUP(H38,Infor!B:F,5,0),) -> L75S7_HVD | G38: BN44-01422A | H38: 0137750274CA | I38: 5000 | J38: =SUM(I38:I39) -> 5070 | L38: =SUMIFS(Stock!$F:$F,Stock!$D:$D,'Shipment '!H38) -> 4422 | M38: =SUMIFS(Plan!$E:$E,Plan!$C:$C,'Shipment '!H38) -> 0 | N38: =SUMIFS(Plan!$F:$F,Plan!$C:$C,'Shipment '!H38) -> 0 | O38: =SUMIFS(Plan!$G:$G,Plan!$C:$C,'Shipment '!H38) -> 0 | P38: =SUMIFS(Plan!$H:$H,Plan!$C:$C,'Shipment '!H38) -> 0 | Q38: =SUMIFS(Plan!$I:$I,Plan!$C:$C,'Shipment '!H38) -> 0 | R38: =SUMIFS(Plan!$J:$J,Plan!$C:$C,'Shipment '!H38) -> 0 | S38: =SUMIFS(Plan!$K:$K,Plan!$C:$C,'Shipment '!H38) -> 0 | T38: =SUMIFS(Plan!$M:$M,Plan!$C:$C,'Shipment '!H38) -> 0 | U38: =SUM(M38:T38) -> 0 | V38: =+L38+U38 -> 4422 | W38: =V38-J38 -> -648
B39: SEDA | C39: Waiting booking | E39: =IFERROR(VLOOKUP(H39,Infor!B:F,4,0),) -> 55" | F39: =IFERROR(VLOOKUP(H39,Infor!B:F,5,0),) -> L55E70A_HVD | G39: BN44-01426A | H39: 0137556092CA | I39: 70 | J39: =SUM(I39:I40) -> 2158 | L39: =SUMIFS(Stock!$F:$F,Stock!$D:$D,'Shipment '!H39) -> 7607 | M39: =SUMIFS(Plan!$E:$E,Plan!$C:$C,'Shipment '!H39) -> 0 | N39: =SUMIFS(Plan!$F:$F,Plan!$C:$C,'Shipment '!H39) -> 0 | O39: =SUMIFS(Plan!$G:$G,Plan!$C:$C,'Shipment '!H39) -> 0 | P39: =SUMIFS(Plan!$H:$H,Plan!$C:$C,'Shipment '!H39) -> 0 | Q39: =SUMIFS(Plan!$I:$I,Plan!$C:$C,'Shipment '!H39) -> 0 | R39: =SUMIFS(Plan!$J:$J,Plan!$C:$C,'Shipment '!H39) -> 0 | S39: =SUMIFS(Plan!$K:$K,Plan!$C:$C,'Shipment '!H39) -> 0 | T39: =SUMIFS(Plan!$M:$M,Plan!$C:$C,'Shipment '!H39) -> 0 | U39: =SUM(M39:T39) -> 0 | V39: =+L39+U39 -> 7607 | W39: =V39-J39 -> 5449
B40: SEDA | C40: Waiting booking | E40: =IFERROR(VLOOKUP(H40,Infor!B:F,4,0),) -> 65" | F40: =IFERROR(VLOOKUP(H40,Infor!B:F,5,0),) -> L65E70A_HVD | G40: BN44-01427A | H40: 0137650511CA | I40: 2088 | J40: =SUM(I40:I41) -> 2989 | L40: =SUMIFS(Stock!$F:$F,Stock!$D:$D,'Shipment '!H40) -> 14423 | N40: =SUMIFS(Plan!$F:$F,Plan!$C:$C,'Shipment '!H40) -> 0 | O40: =SUMIFS(Plan!$G:$G,Plan!$C:$C,'Shipment '!H40) -> 0 | P40: =SUMIFS(Plan!$H:$H,Plan!$C:$C,'Shipment '!H40) -> 0 | Q40: =SUMIFS(Plan!$I:$I,Plan!$C:$C,'Shipment '!H40) -> 0 | R40: =SUMIFS(Plan!$J:$J,Plan!$C:$C,'Shipment '!H40) -> 1462 | S40: =SUMIFS(Plan!$K:$K,Plan!$C:$C,'Shipment '!H40) -> 0 | U40: =SUM(M40:T40) -> 1462 | V40: =+L40+U40 -> 15885 | W40: =V40-J40 -> 12896
...

Sheet Shipment Rev
